Workbook

Sheet Summary
A1: ***อย่าลืมเปิด Macro เพื่อใช้งาน ปุ่มตรวจสอบเลขบัตร/ชื่อ ซ้ำ | O1: กรณีเลขบัตรเป็นคนต่างด้าว ซึ่งมีเลข 0 นำหน้า ระบบจะฟ้องว่า ไม่ครบ 13 หลัก แต่ระบบยังคงนำเข้าฐานข้อมูลได้ตามปกติ | U1: ตารางแสดงผลศักยภาพของพนักงานที่ผ่านการฝึกอบรม
U3: ชื่อ-สกุล | W3: ผลการประเมินศักยภาพผู้ผ่านการอบรม | AB3: รวมคะแนน | AC3: การประเมิน ศักยภาพ | AD3: การประเมิน ผลิตภาพ | AH3: A 1 การเพาะปลูกและการเลี้ยงสัตว์ การล่าสัตว์และกิจกรรมบริการที่เกี่ยวข้อง
W4: 1 | X4: 2 | Y4: 3 | Z4: 4 | AA4: 5 | AH4: A 2 ป่าไม้และการทำไม้
A5: โปรดกรอกผลการประเมินคะแนนพร้อมบันทึกช่วงรายได้ของพนักงานในช่องสีเขียว (หากไม่ยินยอม กรุณาเลือกไม่ยินยอมบันทึกช่วงรายได้) แล้เลือกตัวเลือกศักยภาพในช่องว่างในช่องสีฟ้าเท่านั้น | U5: แดง2 สุขใจ | W5: =INDEX(B8:P107,MATCH(U5,P8:P107,0),6) -> #N/A | X5: =INDEX(B8:P107,MATCH(U5,P8:P107,0),7) -> #N/A | Y5: =INDEX(B8:P107,MATCH(U5,P8:P107,0),8) -> #N/A | Z5: =INDEX(B8:P107,MATCH(U5,P8:P107,0),9) -> #N/A | AA5: =INDEX(B8:P107,MATCH(U5,P8:P107,0),10) -> #N/A | AB5: =INDEX(B8:P107,MATCH(U5,P8:P107,0),11) -> #N/A | AC5: =INDEX(B8:P107,MATCH(U5,P8:P107,0),12) -> #N/A | AD5: =INDEX(B8:P107,MATCH(U5,P8:P107,0),13) -> #N/A | AH5: A 3 การประมงและการเพาะเลี้ยงสัตว์น้ำ
A6: ที่ | B6: เลขบัตรประจำตัวประชาชน | C6: คำนำหน้า | D6: ชื่อ | E6: สกุล | F6: ตำแหน่ง | G6: ผลการประเมินศักยภาพผู้ผ่านการอบรม | L6: การประเมิน ศักยภาพ | M6: การประเมิน ผลิตภาพ | N6: ช่วงรายได้ | O6: ตรวจสอบความถูกต้องของเลขบัตรประชาชน | P6: ชื่อ-สกุล | Q6: STATUS | R6: เช็ค ü หาก ผ่าน | AH6: B 5 การทำเหมืองถ่านหินและลิกไนต์
G7: 1. ความรู้จากการฝึกอบรม | H7: 2. ทักษะในการปฏิบัติงาน | I7: 3. ทัศนคติที่มีต่อการปฏิบัติงาน | J7: 4. การแก้ปัญหาในการทำงาน | K7: 5. ความตระหนักในด้านความปลอดภัย | AH7: B 6 การผลิตน้ำมันดิบและก๊าซธรรมชาติ
A8: 1 | B8: 999999999 | C8: นาย | D8: เสริฐสินธ์ | E8: ธัญญรังสิกุล | F8: หัวหน้างานขายสินค้าทางโทรศัพท์ | G8: 1 | H8: 1 | I8: 1 | J8: 1 | K8: 0 | L8: =IF(ISBLANK(B8),"",IF(SUM(G8:K8)>0,"เพิ่มขึ้น","คงเดิม")) -> เพิ่มขึ้น | M8: =IF(ISBLANK(B8),"",IF(OR(H8>0,J8>0),"เพิ่มขึ้น","คงเดิม")) -> เพิ่มขึ้น | N8: less than 10,000 (น้อยกว่า 10,000) | O8: =IF(ISBLANK(B8),"",IF(LEN(B8)=13,IF(RIGHT(11-MOD(MID(B8,1,1)*13+MID(B8,2,1)*12+MID(B8,3,1)*11+MID(B8,4,1)*10+MID(B8,5,1)*9+MID(B8,6,1)*8+MID(B8,7,1)*7+MID(B8,8,1)*6+MID(B8,9,1)*5+MID(B8,10,1)*4+MID(B8,11,1)*3+MID(B8,12,1)*2,11))=RIGHT(B8),"ถูกต้อง","ผิด "),"ไม่ครบ13หลัก")) -> ไม่ครบ13หลัก | P8: =CONCATENATE(D8," ",E8) -> เสริฐสินธ์ ธัญญรังสิกุล | AH8: B 7 การทำเหมืองสินแร่โลหะ
A9: 2 | B9: 123232323233 | C9: นาย | D9: โกสินทร์ | E9: วุฒิเจริญวงศ์ | F9: กรรมการผู้จัดการ | G9: 0 | H9: 1 | I9: 0 | J9: 1 | K9: 0 | L9: =IF(ISBLANK(B9),"",IF(SUM(G9:K9)>0,"เพิ่มขึ้น","คงเดิม")) -> เพิ่มขึ้น | M9: =IF(ISBLANK(B9),"",IF(OR(H9>0,J9>0),"เพิ่มขึ้น","คงเดิม")) -> เพิ่มขึ้น | N9: less than 10,000 (น้อยกว่า 10,000) | O9: =IF(ISBLANK(B9),"",IF(LEN(B9)=13,IF(RIGHT(11-MOD(MID(B9,1,1)*13+MID(B9,2,1)*12+MID(B9,3,1)*11+MID(B9,4,1)*10+MID(B9,5,1)*9+MID(B9,6,1)*8+MID(B9,7,1)*7+MID(B9,8,1)*6+MID(B9,9,1)*5+MID(B9,10,1)*4+MID(B9,11,1)*3+MID(B9,12,1)*2,11))=RIGHT(B9),"ถูกต้อง","ผิด "),"ไม่ครบ13หลัก")) -> ไม่ครบ13หลัก | P9: =CONCATENATE(D9," ",E9) -> โกสินทร์ วุฒิเจริญวงศ์ | AH9: B 8 การทำเหมืองแร่และเหมืองหินอื่น ๆ
A10: 3 | B10: 6565656565656 | C10: นางสาว | D10: กันยารัตน์ | E10: ดีประเสริฐ | F10: ผู้เชี่ยวชาญงานสนับสนุนธุรกิจและประสบการณ์ลูกค้า | G10: 0 | H10: 1 | I10: 0 | J10: 1 | K10: 0 | L10: =IF(ISBLANK(B10),"",IF(SUM(G10:K10)>0,"เพิ่มขึ้น","คงเดิม")) -> เพิ่มขึ้น | M10: =IF(ISBLANK(B10),"",IF(OR(H10>0,J10>0),"เพิ่มขึ้น","คงเดิม")) -> เพิ่มขึ้น | N10: less than 10,000 (น้อยกว่า 10,000) | O10: =IF(ISBLANK(B10),"",IF(LEN(B10)=13,IF(RIGHT(11-MOD(MID(B10,1,1)*13+MID(B10,2,1)*12+MID(B10,3,1)*11+MID(B10,4,1)*10+MID(B10,5,1)*9+MID(B10,6,1)*8+MID(B10,7,1)*7+MID(B10,8,1)*6+MID(B10,9,1)*5+MID(B10,10,1)*4+MID(B10,11,1)*3+MID(B10,12,1)*2,11))=RIGHT(B10),"ถูกต้อง","ผิด "),"ไม่ครบ13หลัก")) -> ผิด | P10: =CONCATENATE(D10," ",E10) -> กันยารัตน์ ดีประเสริฐ | AH10: B 9 กิจกรรมบริการที่สนับสนุนการทำเหมืองแร่ และสนับสนุนการผลิตปิโตรเลียม
A11: 4 | B11: 777777777 | C11: นาย | D11: จักรกฤษณ์ | E11: กำบังกาย | F11: หัวหน้าทีมวิเคราะห์ข้อมูลและเทคโนโลยีดิจิทัล | G11: 1 | H11: 1 | I11: 2 | J11: 1 | K11: 0 | L11: =IF(ISBLANK(B11),"",IF(SUM(G11:K11)>0,"เพิ่มขึ้น","คงเดิม")) -> เพิ่มขึ้น | M11: =IF(ISBLANK(B11),"",IF(OR(H11>0,J11>0),"เพิ่มขึ้น","คงเดิม")) -> เพิ่มขึ้น | N11: 10,001-20,000 | O11: =IF(ISBLANK(B11),"",IF(LEN(B11)=13,IF(RIGHT(11-MOD(MID(B11,1,1)*13+MID(B11,2,1)*12+MID(B11,3,1)*11+MID(B11,4,1)*10+MID(B11,5,1)*9+MID(B11,6,1)*8+MID(B11,7,1)*7+MID(B11,8,1)*6+MID(B11,9,1)*5+MID(B11,10,1)*4+MID(B11,11,1)*3+MID(B11,12,1)*2,11))=RIGHT(B11),"ถูกต้อง","ผิด "),"ไม่ครบ13หลัก")) -> ไม่ครบ13หลัก | P11: =CONCATENATE(D11," ",E11) -> จักรกฤษณ์ กำบังกาย | AH11: C 10 การผลิตผลิตภัณฑ์อาหาร
A12: 5 | B12: 88888888 | C12: นาย | D12: ชัยเมศร์ | E12: วรสมบูรณ์ไชย | F12: หัวหน้างานขายสินค้าทางโทรศัพท์ | G12: 1 | H12: 1 | I12: 2 | J12: 1 | K12: 0 | L12: =IF(ISBLANK(B12),"",IF(SUM(G12:K12)>0,"เพิ่มขึ้น","คงเดิม")) -> เพิ่มขึ้น | M12: =IF(ISBLANK(B12),"",IF(OR(H12>0,J12>0),"เพิ่มขึ้น","คงเดิม")) -> เพิ่มขึ้น | N12: 30,001-40,000 | O12: =IF(ISBLANK(B12),"",IF(LEN(B12)=13,IF(RIGHT(11-MOD(MID(B12,1,1)*13+MID(B12,2,1)*12+MID(B12,3,1)*11+MID(B12,4,1)*10+MID(B12,5,1)*9+MID(B12,6,1)*8+MID(B12,7,1)*7+MID(B12,8,1)*6+MID(B12,9,1)*5+MID(B12,10,1)*4+MID(B12,11,1)*3+MID(B12,12,1)*2,11))=RIGHT(B12),"ถูกต้อง","ผิด "),"ไม่ครบ13หลัก")) -> ไม่ครบ13หลัก | P12: =CONCATENATE(D12," ",E12) -> ชัยเมศร์ วรสมบูรณ์ไชย | AH12: C 11 การผลิตเครื่องดื่ม
A13: 6 | B13: 999999999 | C13: นางสาว | D13: ฐายิกา | E13: ทัศนีย์ | F13: พนักงานบริการหลังการขาย | G13: 1 | H13: 1 | I13: 1 | J13: 1 | K13: 0 | L13: =IF(ISBLANK(B13),"",IF(SUM(G13:K13)>0,"เพิ่มขึ้น","คงเดิม")) -> เพิ่มขึ้น | M13: =IF(ISBLANK(B13),"",IF(OR(H13>0,J13>0),"เพิ่มขึ้น","คงเดิม")) -> เพิ่มขึ้น | N13: 10,001-20,000 | O13: =IF(ISBLANK(B13),"",IF(LEN(B13)=13,IF(RIGHT(11-MOD(MID(B13,1,1)*13+MID(B13,2,1)*12+MID(B13,3,1)*11+MID(B13,4,1)*10+MID(B13,5,1)*9+MID(B13,6,1)*8+MID(B13,7,1)*7+MID(B13,8,1)*6+MID(B13,9,1)*5+MID(B13,10,1)*4+MID(B13,11,1)*3+MID(B13,12,1)*2,11))=RIGHT(B13),"ถูกต้อง","ผิด "),"ไม่ครบ13หลัก")) -> ไม่ครบ13หลัก | P13: =CONCATENATE(D13," ",E13) -> ฐายิกา ทัศนีย์ | AH13: C 12 การผลิตสิ่งทอ
A14: 7 | C14: นาย | D14: ณัฐณิชา | E14: สมพานต์ | F14: หัวหน้าทีมการตลาดเนื้อหาและสร้างสรรค์ | G14: 1 | H14: 2 | I14: 1 | J14: 1 | K14: 0 | L14: =IF(ISBLANK(B14),"",IF(SUM(G14:K14)>0,"เพิ่มขึ้น","คงเดิม")) | M14: =IF(ISBLANK(B14),"",IF(OR(H14>0,J14>0),"เพิ่มขึ้น","คงเดิม")) | O14: =IF(ISBLANK(B14),"",IF(LEN(B14)=13,IF(RIGHT(11-MOD(MID(B14,1,1)*13+MID(B14,2,1)*12+MID(B14,3,1)*11+MID(B14,4,1)*10+MID(B14,5,1)*9+MID(B14,6,1)*8+MID(B14,7,1)*7+MID(B14,8,1)*6+MID(B14,9,1)*5+MID(B14,10,1)*4+MID(B14,11,1)*3+MID(B14,12,1)*2,11))=RIGHT(B14),"ถูกต้อง","ผิด "),"ไม่ครบ13หลัก")) | P14: =CONCATENATE(D14," ",E14) -> ณัฐณิชา สมพานต์ | AH14: C 13 การผลิตเสื้อผ้าเครื่องแต่งกาย
A15: 8 | C15: นาย | D15: ณัฐพัฒน์ | E15: สุขใส | F15: นักวิเคราะห์ข้อมูลธุรกิจ | G15: 1 | H15: 1 | I15: 1 | J15: 1 | K15: 0 | L15: =IF(ISBLANK(B15),"",IF(SUM(G15:K15)>0,"เพิ่มขึ้น","คงเดิม")) | M15: =IF(ISBLANK(B15),"",IF(OR(H15>0,J15>0),"เพิ่มขึ้น","คงเดิม")) | O15: =IF(ISBLANK(B15),"",IF(LEN(B15)=13,IF(RIGHT(11-MOD(MID(B15,1,1)*13+MID(B15,2,1)*12+MID(B15,3,1)*11+MID(B15,4,1)*10+MID(B15,5,1)*9+MID(B15,6,1)*8+MID(B15,7,1)*7+MID(B15,8,1)*6+MID(B15,9,1)*5+MID(B15,10,1)*4+MID(B15,11,1)*3+MID(B15,12,1)*2,11))=RIGHT(B15),"ถูกต้อง","ผิด "),"ไม่ครบ13หลัก")) | P15: =CONCATENATE(D15," ",E15) -> ณัฐพัฒน์ สุขใส | AH15: C 14 การผลิตเครื่องหนัง และผลิตภัณฑ์ที่เกี่ยวข้อง
A16: 9 | C16: นางสาว | D16: ดีลยา | E16: รุจิรอานนท์ | F16: พนักงานขายดูแลลูกค้ารายใหญ่ | G16: 1 | H16: 1 | I16: 1 | J16: 1 | K16: 0 | L16: =IF(ISBLANK(B16),"",IF(SUM(G16:K16)>0,"เพิ่มขึ้น","คงเดิม")) | M16: =IF(ISBLANK(B16),"",IF(OR(H16>0,J16>0),"เพิ่มขึ้น","คงเดิม")) | O16: =IF(ISBLANK(B16),"",IF(LEN(B16)=13,IF(RIGHT(11-MOD(MID(B16,1,1)*13+MID(B16,2,1)*12+MID(B16,3,1)*11+MID(B16,4,1)*10+MID(B16,5,1)*9+MID(B16,6,1)*8+MID(B16,7,1)*7+MID(B16,8,1)*6+MID(B16,9,1)*5+MID(B16,10,1)*4+MID(B16,11,1)*3+MID(B16,12,1)*2,11))=RIGHT(B16),"ถูกต้อง","ผิด "),"ไม่ครบ13หลัก")) | P16: =CONCATENATE(D16," ",E16) -> ดีลยา รุจิรอานนท์ | U16: สรุปภาพรวมการฝึกอบรม | AH16: C 15 การผลิตไม้และผลิตภัณฑ์จากไม้ และไม้ก๊อก ยกเว้น เฟอร์นิเจอร์ การผลิตสิ่งของจากฟางและวัสดุถักสานอื่น ๆ
A17: 10 | C17: นางสาว | D17: ตรีจุฑา | E17: สรวงท่าไม้ | F17: กรรมการบริหาร | G17: 1 | H17: 1 | I17: 1 | J17: 1 | K17: 0 | L17: =IF(ISBLANK(B17),"",IF(SUM(G17:K17)>0,"เพิ่มขึ้น","คงเดิม")) | M17: =IF(ISBLANK(B17),"",IF(OR(H17>0,J17>0),"เพิ่มขึ้น","คงเดิม")) | O17: =IF(ISBLANK(B17),"",IF(LEN(B17)=13,IF(RIGHT(11-MOD(MID(B17,1,1)*13+MID(B17,2,1)*12+MID(B17,3,1)*11+MID(B17,4,1)*10+MID(B17,5,1)*9+MID(B17,6,1)*8+MID(B17,7,1)*7+MID(B17,8,1)*6+MID(B17,9,1)*5+MID(B17,10,1)*4+MID(B17,11,1)*3+MID(B17,12,1)*2,11))=RIGHT(B17),"ถูกต้อง","ผิด "),"ไม่ครบ13หลัก")) | P17: =CONCATENATE(D17," ",E17) -> ตรีจุฑา สรวงท่าไม้ | U17: มีพนักงานที่เข้าร่วมอบรมทั้งหมด | AB17: จำนวน | AC17: =COUNTA(C8:C107) -> 29 | AD17: คน | AH17: C 16 การผลิตกระดาษและ ผลิตภัณฑ์ที่แปรรูปจากกระดาษ
A18: 11 | C18: นางสาว | D18: ทิพย์สุดา | E18: ปลื้มใจ | F18: หัวหน้าทีมพัฒนาผลิตภัณฑ์และตรวจสอบคุณภาพ | G18: 1 | H18: 1 | I18: 1 | J18: 1 | K18: 0 | L18: =IF(ISBLANK(B18),"",IF(SUM(G18:K18)>0,"เพิ่มขึ้น","คงเดิม")) | M18: =IF(ISBLANK(B18),"",IF(OR(H18>0,J18>0),"เพิ่มขึ้น","คงเดิม")) | O18: =IF(ISBLANK(B18),"",IF(LEN(B18)=13,IF(RIGHT(11-MOD(MID(B18,1,1)*13+MID(B18,2,1)*12+MID(B18,3,1)*11+MID(B18,4,1)*10+MID(B18,5,1)*9+MID(B18,6,1)*8+MID(B18,7,1)*7+MID(B18,8,1)*6+MID(B18,9,1)*5+MID(B18,10,1)*4+MID(B18,11,1)*3+MID(B18,12,1)*2,11))=RIGHT(B18),"ถูกต้อง","ผิด "),"ไม่ครบ13หลัก")) | P18: =CONCATENATE(D18," ",E18) -> ทิพย์สุดา ปลื้มใจ | U18: จำนวนผู้ผ่านการอบรมที่มีผลการพัฒนาศักยภาพเพิ่มขึ้น | AB18: จำนวน | AC18: =COUNTIF(L8:L107,"เพิ่มขึ้น") -> 6 | AD18: คน | AH18: C 17 การพิมพ์ และการผลิตซ้ำสื่อบันทึก
A19: 12 | C19: นางสาว | D19: ธนภัค | E19: เต๊ะชัย | F19: ผู้ช่วยผู้บริหาร | G19: 1 | H19: 1 | I19: 1 | J19: 1 | K19: 0 | L19: =IF(ISBLANK(B19),"",IF(SUM(G19:K19)>0,"เพิ่มขึ้น","คงเดิม")) | M19: =IF(ISBLANK(B19),"",IF(OR(H19>0,J19>0),"เพิ่มขึ้น","คงเดิม")) | O19: =IF(ISBLANK(B19),"",IF(LEN(B19)=13,IF(RIGHT(11-MOD(MID(B19,1,1)*13+MID(B19,2,1)*12+MID(B19,3,1)*11+MID(B19,4,1)*10+MID(B19,5,1)*9+MID(B19,6,1)*8+MID(B19,7,1)*7+MID(B19,8,1)*6+MID(B19,9,1)*5+MID(B19,10,1)*4+MID(B19,11,1)*3+MID(B19,12,1)*2,11))=RIGHT(B19),"ถูกต้อง","ผิด "),"ไม่ครบ13หลัก")) | P19: =CONCATENATE(D19," ",E19) -> ธนภัค เต๊ะชัย | U19: จำนวนผู้ผ่านการอบรมที่มีผลิตภาพแรงงานเพิ่มขึ้น | AB19: จำนวน | AC19: =COUNTIF(M8:M107,"เพิ่มขึ้น") -> 6 | AD19: คน | AH19: C 18 การผลิตถ่านโค้ก และผลิตภัณฑ์จากการกลั่นปิโตรเลียม
A20: 13 | C20: นาย | D20: ธนรัตน์ | E20: รอดพ่าย | F20: พนักงานพัฒนาทรัพยากรบุคคลอาวุโส | G20: 1 | H20: 1 | I20: 1 | J20: 1 | K20: 0 | L20: =IF(ISBLANK(B20),"",IF(SUM(G20:K20)>0,"เพิ่มขึ้น","คงเดิม")) | M20: =IF(ISBLANK(B20),"",IF(OR(H20>0,J20>0),"เพิ่มขึ้น","คงเดิม")) | O20: =IF(ISBLANK(B20),"",IF(LEN(B20)=13,IF(RIGHT(11-MOD(MID(B20,1,1)*13+MID(B20,2,1)*12+MID(B20,3,1)*11+MID(B20,4,1)*10+MID(B20,5,1)*9+MID(B20,6,1)*8+MID(B20,7,1)*7+MID(B20,8,1)*6+MID(B20,9,1)*5+MID(B20,10,1)*4+MID(B20,11,1)*3+MID(B20,12,1)*2,11))=RIGHT(B20),"ถูกต้อง","ผิด "),"ไม่ครบ13หลัก")) | P20: =CONCATENATE(D20," ",E20) -> ธนรัตน์ รอดพ่าย | AH20: C 19 การผลิตเคมีภัณฑ์ และผลิตภัณฑ์เคมี
A21: 14 | C21: นางสาว | D21: ธนานิษฐ์ | E21: ธนาสิริฐานันท์ | F21: หัวหน้างานขายสินค้าออนไลน์ | G21: 1 | H21: 1 | I21: 1 | J21: 1 | K21: 0 | L21: =IF(ISBLANK(B21),"",IF(SUM(G21:K21)>0,"เพิ่มขึ้น","คงเดิม")) | M21: =IF(ISBLANK(B21),"",IF(OR(H21>0,J21>0),"เพิ่มขึ้น","คงเดิม")) | O21: =IF(ISBLANK(B21),"",IF(LEN(B21)=13,IF(RIGHT(11-MOD(MID(B21,1,1)*13+MID(B21,2,1)*12+MID(B21,3,1)*11+MID(B21,4,1)*10+MID(B21,5,1)*9+MID(B21,6,1)*8+MID(B21,7,1)*7+MID(B21,8,1)*6+MID(B21,9,1)*5+MID(B21,10,1)*4+MID(B21,11,1)*3+MID(B21,12,1)*2,11))=RIGHT(B21),"ถูกต้อง","ผิด "),"ไม่ครบ13หลัก")) | P21: =CONCATENATE(D21," ",E21) -> ธนานิษฐ์ ธนาสิริฐานันท์ | U21: 1. ความรู้จากการฝึกอบรม | AB21: เฉลี่ย | AC21: =ROUND(AVERAGE(G8:G107),2) -> 0.93 | AD21: คะแนน | AH21: C 20 การผลิตเภสัชภัณฑ์พื้นฐานและการผลิตสูตรตำรับทางเภสัชกรรม
A22: 15 | C22: นางสาว | D22: ธัญชนก | E22: กฤดิกุล | F22: หัวหน้าทีม KOL Affiliate และ Live Management | G22: 1 | H22: 1 | I22: 1 | J22: 1 | K22: 0 | L22: =IF(ISBLANK(B22),"",IF(SUM(G22:K22)>0,"เพิ่มขึ้น","คงเดิม")) | M22: =IF(ISBLANK(B22),"",IF(OR(H22>0,J22>0),"เพิ่มขึ้น","คงเดิม")) | O22: =IF(ISBLANK(B22),"",IF(LEN(B22)=13,IF(RIGHT(11-MOD(MID(B22,1,1)*13+MID(B22,2,1)*12+MID(B22,3,1)*11+MID(B22,4,1)*10+MID(B22,5,1)*9+MID(B22,6,1)*8+MID(B22,7,1)*7+MID(B22,8,1)*6+MID(B22,9,1)*5+MID(B22,10,1)*4+MID(B22,11,1)*3+MID(B22,12,1)*2,11))=RIGHT(B22),"ถูกต้อง","ผิด "),"ไม่ครบ13หลัก")) | P22: =CONCATENATE(D22," ",E22) -> ธัญชนก กฤดิกุล | U22: 2. ทักษะในการปฏิบัติงาน | AB22: เฉลี่ย | AC22: =AVERAGE(H8:H107) -> 1.0344828 | AD22: คะแนน | AH22: C 21 การผลิตผลิตภัณฑ์ยางและพลาสติก
A23: 16 | C23: นาย | D23: นฤพล | E23: พันธุ์จบสิงห์ | F23: หัวหน้างานบัญชีและการเงิน | G23: 1 | H23: 1 | I23: 1 | J23: 1 | K23: 0 | L23: =IF(ISBLANK(B23),"",IF(SUM(G23:K23)>0,"เพิ่มขึ้น","คงเดิม")) | M23: =IF(ISBLANK(B23),"",IF(OR(H23>0,J23>0),"เพิ่มขึ้น","คงเดิม")) | O23: =IF(ISBLANK(B23),"",IF(LEN(B23)=13,IF(RIGHT(11-MOD(MID(B23,1,1)*13+MID(B23,2,1)*12+MID(B23,3,1)*11+MID(B23,4,1)*10+MID(B23,5,1)*9+MID(B23,6,1)*8+MID(B23,7,1)*7+MID(B23,8,1)*6+MID(B23,9,1)*5+MID(B23,10,1)*4+MID(B23,11,1)*3+MID(B23,12,1)*2,11))=RIGHT(B23),"ถูกต้อง","ผิด "),"ไม่ครบ13หลัก")) | P23: =CONCATENATE(D23," ",E23) -> นฤพล พันธุ์จบสิงห์ | U23: 3. ทัศนคติที่มีต่อการปฏิบัติงาน | AB23: เฉลี่ย | AC23: =AVERAGE(I8:I107) -> 1 | AD23: คะแนน | AH23: C 22 การผลิตผลิตภัณฑ์อื่น ๆ ที่ทำจากแร่อโลหะ
A24: 17 | C24: นางสาว | D24: นันทวัน | E24: ศิรเกียรติพล | F24: เจ้าหน้าที่จัดซื้ออาวุโส | G24: 1 | H24: 1 | I24: 1 | J24: 1 | K24: 0 | L24: =IF(ISBLANK(B24),"",IF(SUM(G24:K24)>0,"เพิ่มขึ้น","คงเดิม")) | M24: =IF(ISBLANK(B24),"",IF(OR(H24>0,J24>0),"เพิ่มขึ้น","คงเดิม")) | O24: =IF(ISBLANK(B24),"",IF(LEN(B24)=13,IF(RIGHT(11-MOD(MID(B24,1,1)*13+MID(B24,2,1)*12+MID(B24,3,1)*11+MID(B24,4,1)*10+MID(B24,5,1)*9+MID(B24,6,1)*8+MID(B24,7,1)*7+MID(B24,8,1)*6+MID(B24,9,1)*5+MID(B24,10,1)*4+MID(B24,11,1)*3+MID(B24,12,1)*2,11))=RIGHT(B24),"ถูกต้อง","ผิด "),"ไม่ครบ13หลัก")) | P24: =CONCATENATE(D24," ",E24) -> นันทวัน ศิรเกียรติพล | U24: 4. การแก้ปัญหาในการทำงาน | AB24: เฉลี่ย | AC24: =AVERAGE(J8:J107) -> 1 | AD24: คะแนน | AH24: C 23 การผลิตโลหะขั้นมูลฐาน
A25: 18 | C25: นางสาว | D25: นับเดือน | E25: แพ่งกลิ่น | F25: พนักงานบริการหลังการขายอาวุโส | G25: 1 | H25: 1 | I25: 1 | J25: 1 | K25: 0 | L25: =IF(ISBLANK(B25),"",IF(SUM(G25:K25)>0,"เพิ่มขึ้น","คงเดิม")) | M25: =IF(ISBLANK(B25),"",IF(OR(H25>0,J25>0),"เพิ่มขึ้น","คงเดิม")) | O25: =IF(ISBLANK(B25),"",IF(LEN(B25)=13,IF(RIGHT(11-MOD(MID(B25,1,1)*13+MID(B25,2,1)*12+MID(B25,3,1)*11+MID(B25,4,1)*10+MID(B25,5,1)*9+MID(B25,6,1)*8+MID(B25,7,1)*7+MID(B25,8,1)*6+MID(B25,9,1)*5+MID(B25,10,1)*4+MID(B25,11,1)*3+MID(B25,12,1)*2,11))=RIGHT(B25),"ถูกต้อง","ผิด "),"ไม่ครบ13หลัก")) | P25: =CONCATENATE(D25," ",E25) -> นับเดือน แพ่งกลิ่น | U25: 5. ความตระหนักในด้านความปลอดภัย | AB25: เฉลี่ย | AC25: =AVERAGE(K8:K107) -> 0 | AD25: คะแนน | AH25: C 24 การผลิตผลิตภัณฑ์ที่ทำจากโลหะประดิษฐ์ ยกเว้น เครื่องจักรและอุปกรณ์
A26: 19 | C26: นาง | D26: นาฏยา | E26: ทัศนีย์ | F26: หัวหน้าสายงานปฏิบัติการ | G26: 1 | H26: 1 | I26: 1 | J26: 1 | K26: 0 | L26: =IF(ISBLANK(B26),"",IF(SUM(G26:K26)>0,"เพิ่มขึ้น","คงเดิม")) | M26: =IF(ISBLANK(B26),"",IF(OR(H26>0,J26>0),"เพิ่มขึ้น","คงเดิม")) | O26: =IF(ISBLANK(B26),"",IF(LEN(B26)=13,IF(RIGHT(11-MOD(MID(B26,1,1)*13+MID(B26,2,1)*12+MID(B26,3,1)*11+MID(B26,4,1)*10+MID(B26,5,1)*9+MID(B26,6,1)*8+MID(B26,7,1)*7+MID(B26,8,1)*6+MID(B26,9,1)*5+MID(B26,10,1)*4+MID(B26,11,1)*3+MID(B26,12,1)*2,11))=RIGHT(B26),"ถูกต้อง","ผิด "),"ไม่ครบ13หลัก")) | P26: =CONCATENATE(D26," ",E26) -> นาฏยา ทัศนีย์ | U26: คะแนนทุกเกณฑ์การประเมิน | AB26: เฉลี่ย | AC26: =AVERAGE(AC21:AC25) -> 0.79289655 | AD26: คะแนน | AH26: C 25 การผลิตผลิตภัณฑ์คอมพิวเตอร์ อิเล็กทรอนิกส์ และอุปกรณ์ทางทัศนศาสตร์
A27: 20 | C27: นาย | D27: พลพัฒน์ | E27: ทิมหาญ | F27: ผู้จัดการฝ่ายขาย | G27: 1 | H27: 1 | I27: 1 | J27: 1 | K27: 0 | L27: =IF(ISBLANK(B27),"",IF(SUM(G27:K27)>0,"เพิ่มขึ้น","คงเดิม")) | M27: =IF(ISBLANK(B27),"",IF(OR(H27>0,J27>0),"เพิ่มขึ้น","คงเดิม")) | O27: =IF(ISBLANK(B27),"",IF(LEN(B27)=13,IF(RIGHT(11-MOD(MID(B27,1,1)*13+MID(B27,2,1)*12+MID(B27,3,1)*11+MID(B27,4,1)*10+MID(B27,5,1)*9+MID(B27,6,1)*8+MID(B27,7,1)*7+MID(B27,8,1)*6+MID(B27,9,1)*5+MID(B27,10,1)*4+MID(B27,11,1)*3+MID(B27,12,1)*2,11))=RIGHT(B27),"ถูกต้อง","ผิด "),"ไม่ครบ13หลัก")) | P27: =CONCATENATE(D27," ",E27) -> พลพัฒน์ ทิมหาญ | AH27: C 26 การผลิตอุปกรณ์ไฟฟ้า
A28: 21 | C28: นางสาว | D28: ภัควดี | E28: มณี | F28: ผู้ช่วยผู้บริหาร | G28: 1 | H28: 1 | I28: 1 | J28: 1 | K28: 0 | L28: =IF(ISBLANK(B28),"",IF(SUM(G28:K28)>0,"เพิ่มขึ้น","คงเดิม")) | M28: =IF(ISBLANK(B28),"",IF(OR(H28>0,J28>0),"เพิ่มขึ้น","คงเดิม")) | O28: =IF(ISBLANK(B28),"",IF(LEN(B28)=13,IF(RIGHT(11-MOD(MID(B28,1,1)*13+MID(B28,2,1)*12+MID(B28,3,1)*11+MID(B28,4,1)*10+MID(B28,5,1)*9+MID(B28,6,1)*8+MID(B28,7,1)*7+MID(B28,8,1)*6+MID(B28,9,1)*5+MID(B28,10,1)*4+MID(B28,11,1)*3+MID(B28,12,1)*2,11))=RIGHT(B28),"ถูกต้อง","ผิด "),"ไม่ครบ13หลัก")) | P28: =CONCATENATE(D28," ",E28) -> ภัควดี มณี | W28: less than 10,000 (น้อยกว่า 10,000) | AH28: C 27 การผลิตเครื่องจักรและเครื่องมือ ซึ่งมิได้จัดประเภทไว้ในที่อื่น
A29: 22 | C29: นางสาว | D29: ภัทรมน | E29: ธงไชย | F29: พนักงานพัฒนาองค์กรอาวุโส | G29: 1 | H29: 1 | I29: 1 | J29: 1 | K29: 0 | L29: =IF(ISBLANK(B29),"",IF(SUM(G29:K29)>0,"เพิ่มขึ้น","คงเดิม")) | M29: =IF(ISBLANK(B29),"",IF(OR(H29>0,J29>0),"เพิ่มขึ้น","คงเดิม")) | O29: =IF(ISBLANK(B29),"",IF(LEN(B29)=13,IF(RIGHT(11-MOD(MID(B29,1,1)*13+MID(B29,2,1)*12+MID(B29,3,1)*11+MID(B29,4,1)*10+MID(B29,5,1)*9+MID(B29,6,1)*8+MID(B29,7,1)*7+MID(B29,8,1)*6+MID(B29,9,1)*5+MID(B29,10,1)*4+MID(B29,11,1)*3+MID(B29,12,1)*2,11))=RIGHT(B29),"ถูกต้อง","ผิด "),"ไม่ครบ13หลัก")) | P29: =CONCATENATE(D29," ",E29) -> ภัทรมน ธงไชย | W29: 10,001-20,000 | AH29: C 28 การผลิตยานยนต์ รถพ่วงและรถกึ่งพ่วง
A30: 23 | C30: นางสาว | D30: มาลา | E30: นาคสุวรรณ | F30: ผู้เชี่ยวชาญงานทรัพยากรบุคคล | G30: 1 | H30: 1 | I30: 1 | J30: 1 | K30: 0 | L30: =IF(ISBLANK(B30),"",IF(SUM(G30:K30)>0,"เพิ่มขึ้น","คงเดิม")) | M30: =IF(ISBLANK(B30),"",IF(OR(H30>0,J30>0),"เพิ่มขึ้น","คงเดิม")) | O30: =IF(ISBLANK(B30),"",IF(LEN(B30)=13,IF(RIGHT(11-MOD(MID(B30,1,1)*13+MID(B30,2,1)*12+MID(B30,3,1)*11+MID(B30,4,1)*10+MID(B30,5,1)*9+MID(B30,6,1)*8+MID(B30,7,1)*7+MID(B30,8,1)*6+MID(B30,9,1)*5+MID(B30,10,1)*4+MID(B30,11,1)*3+MID(B30,12,1)*2,11))=RIGHT(B30),"ถูกต้อง","ผิด "),"ไม่ครบ13หลัก")) | P30: =CONCATENATE(D30," ",E30) -> มาลา นาคสุวรรณ | W30: 20,001-30,000 | AH30: C 29 การผลิตอุปกรณ์ขนส่งอื่น ๆ
A31: 24 | C31: นางสาว | D31: รุ่งระวี | E31: ทองมลีวรรณ์ | F31: หัวหน้างานคลังสินค้า | G31: 1 | H31: 1 | I31: 1 | J31: 1 | K31: 0 | L31: =IF(ISBLANK(B31),"",IF(SUM(G31:K31)>0,"เพิ่มขึ้น","คงเดิม")) | M31: =IF(ISBLANK(B31),"",IF(OR(H31>0,J31>0),"เพิ่มขึ้น","คงเดิม")) | O31: =IF(ISBLANK(B31),"",IF(LEN(B31)=13,IF(RIGHT(11-MOD(MID(B31,1,1)*13+MID(B31,2,1)*12+MID(B31,3,1)*11+MID(B31,4,1)*10+MID(B31,5,1)*9+MID(B31,6,1)*8+MID(B31,7,1)*7+MID(B31,8,1)*6+MID(B31,9,1)*5+MID(B31,10,1)*4+MID(B31,11,1)*3+MID(B31,12,1)*2,11))=RIGHT(B31),"ถูกต้อง","ผิด "),"ไม่ครบ13หลัก")) | P31: =CONCATENATE(D31," ",E31) -> รุ่งระวี ทองมลีวรรณ์ | W31: 30,001-40,000 | AH31: C 30 การผลิตเฟอร์นิเจอร์
A32: 25 | C32: นางสาว | D32: พรทิวา | E32: สร้อยมาลัย | F32: พนักงานการตลาดโครงการอาวุโส | G32: 1 | H32: 1 | I32: 1 | J32: 1 | K32: 0 | L32: =IF(ISBLANK(B32),"",IF(SUM(G32:K32)>0,"เพิ่มขึ้น","คงเดิม")) | M32: =IF(ISBLANK(B32),"",IF(OR(H32>0,J32>0),"เพิ่มขึ้น","คงเดิม")) | O32: =IF(ISBLANK(B32),"",IF(LEN(B32)=13,IF(RIGHT(11-MOD(MID(B32,1,1)*13+MID(B32,2,1)*12+MID(B32,3,1)*11+MID(B32,4,1)*10+MID(B32,5,1)*9+MID(B32,6,1)*8+MID(B32,7,1)*7+MID(B32,8,1)*6+MID(B32,9,1)*5+MID(B32,10,1)*4+MID(B32,11,1)*3+MID(B32,12,1)*2,11))=RIGHT(B32),"ถูกต้อง","ผิด "),"ไม่ครบ13หลัก")) | P32: =CONCATENATE(D32," ",E32) -> พรทิวา สร้อยมาลัย | W32: 40,001-50,000 | AH32: C 31 การผลิตผลิตภัณฑ์ประเภทอื่น ๆ
A33: 26 | C33: นางสาว | D33: ศศิมา | E33: เทแก้ว | F33: หัวหน้าทีมการตลาดดิจิทัล | G33: 1 | H33: 1 | I33: 1 | J33: 1 | K33: 0 | L33: =IF(ISBLANK(B33),"",IF(SUM(G33:K33)>0,"เพิ่มขึ้น","คงเดิม")) | M33: =IF(ISBLANK(B33),"",IF(OR(H33>0,J33>0),"เพิ่มขึ้น","คงเดิม")) | O33: =IF(ISBLANK(B33),"",IF(LEN(B33)=13,IF(RIGHT(11-MOD(MID(B33,1,1)*13+MID(B33,2,1)*12+MID(B33,3,1)*11+MID(B33,4,1)*10+MID(B33,5,1)*9+MID(B33,6,1)*8+MID(B33,7,1)*7+MID(B33,8,1)*6+MID(B33,9,1)*5+MID(B33,10,1)*4+MID(B33,11,1)*3+MID(B33,12,1)*2,11))=RIGHT(B33),"ถูกต้อง","ผิด "),"ไม่ครบ13หลัก")) | P33: =CONCATENATE(D33," ",E33) -> ศศิมา เทแก้ว | W33: more than 50,001 (มากกว่า 50,001) | AH33: C 32 การซ่อม และการติดตั้งเครื่องจักรและอุปกรณ์
A34: 27 | C34: นางสาว | D34: อรธิรา | E34: เฉลิมถ้อย | F34: พนักงานบริหารทรัพยากรบุคคลอาวุโส | G34: 1 | H34: 1 | I34: 1 | J34: 1 | K34: 0 | L34: =IF(ISBLANK(B34),"",IF(SUM(G34:K34)>0,"เพิ่มขึ้น","คงเดิม")) | M34: =IF(ISBLANK(B34),"",IF(OR(H34>0,J34>0),"เพิ่มขึ้น","คงเดิม")) | O34: =IF(ISBLANK(B34),"",IF(LEN(B34)=13,IF(RIGHT(11-MOD(MID(B34,1,1)*13+MID(B34,2,1)*12+MID(B34,3,1)*11+MID(B34,4,1)*10+MID(B34,5,1)*9+MID(B34,6,1)*8+MID(B34,7,1)*7+MID(B34,8,1)*6+MID(B34,9,1)*5+MID(B34,10,1)*4+MID(B34,11,1)*3+MID(B34,12,1)*2,11))=RIGHT(B34),"ถูกต้อง","ผิด "),"ไม่ครบ13หลัก")) | P34: =CONCATENATE(D34," ",E34) -> อรธิรา เฉลิมถ้อย | W34: N/A (ไม่ระบุ) | AH34: C 33 การผลิตผลิตภัณฑ์จากยาสูบ
A35: 28 | C35: นางสาว | D35: อรวรรณ | E35: วงศ์ธนากรชัย | F35: หัวหน้าสายงานการตลาด | G35: 1 | H35: 1 | I35: 1 | J35: 1 | K35: 0 | L35: =IF(ISBLANK(B35),"",IF(SUM(G35:K35)>0,"เพิ่มขึ้น","คงเดิม")) | M35: =IF(ISBLANK(B35),"",IF(OR(H35>0,J35>0),"เพิ่มขึ้น","คงเดิม")) | O35: =IF(ISBLANK(B35),"",IF(LEN(B35)=13,IF(RIGHT(11-MOD(MID(B35,1,1)*13+MID(B35,2,1)*12+MID(B35,3,1)*11+MID(B35,4,1)*10+MID(B35,5,1)*9+MID(B35,6,1)*8+MID(B35,7,1)*7+MID(B35,8,1)*6+MID(B35,9,1)*5+MID(B35,10,1)*4+MID(B35,11,1)*3+MID(B35,12,1)*2,11))=RIGHT(B35),"ถูกต้อง","ผิด "),"ไม่ครบ13หลัก")) | P35: =CONCATENATE(D35," ",E35) -> อรวรรณ วงศ์ธนากรชัย | AH35: D 35 ไฟฟ้า ก๊าซ ไอน้ำและระบบการปรับอากาศ
A36: 29 | C36: นางสาว | D36: อารยา | E36: พึ่งมี | F36: พนักงานตรวจสอบคุณภาพการขาย | G36: 1 | H36: 1 | I36: 1 | J36: 1 | K36: 0 | L36: =IF(ISBLANK(B36),"",IF(SUM(G36:K36)>0,"เพิ่มขึ้น","คงเดิม")) | M36: =IF(ISBLANK(B36),"",IF(OR(H36>0,J36>0),"เพิ่มขึ้น","คงเดิม")) | O36: =IF(ISBLANK(B36),"",IF(LEN(B36)=13,IF(RIGHT(11-MOD(MID(B36,1,1)*13+MID(B36,2,1)*12+MID(B36,3,1)*11+MID(B36,4,1)*10+MID(B36,5,1)*9+MID(B36,6,1)*8+MID(B36,7,1)*7+MID(B36,8,1)*6+MID(B36,9,1)*5+MID(B36,10,1)*4+MID(B36,11,1)*3+MID(B36,12,1)*2,11))=RIGHT(B36),"ถูกต้อง","ผิด "),"ไม่ครบ13หลัก")) | P36: =CONCATENATE(D36," ",E36) -> อารยา พึ่งมี | AH36: E 36 การเก็บกักน้ำ การจัดหาน้ำ และการจ่ายน้ำ
L37: =IF(ISBLANK(B37),"",IF(SUM(G37:K37)>0,"เพิ่มขึ้น","คงเดิม")) | M37: =IF(ISBLANK(B37),"",IF(OR(H37>0,J37>0),"เพิ่มขึ้น","คงเดิม")) | O37: =IF(ISBLANK(B37),"",IF(LEN(B37)=13,IF(RIGHT(11-MOD(MID(B37,1,1)*13+MID(B37,2,1)*12+MID(B37,3,1)*11+MID(B37,4,1)*10+MID(B37,5,1)*9+MID(B37,6,1)*8+MID(B37,7,1)*7+MID(B37,8,1)*6+MID(B37,9,1)*5+MID(B37,10,1)*4+MID(B37,11,1)*3+MID(B37,12,1)*2,11))=RIGHT(B37),"ถูกต้อง","ผิด "),"ไม่ครบ13หลัก")) | P37: =CONCATENATE(D37," ",E37) | AH37: E 37 การจัดการน้ำเสีย
L38: =IF(ISBLANK(B38),"",IF(SUM(G38:K38)>0,"เพิ่มขึ้น","คงเดิม")) | M38: =IF(ISBLANK(B38),"",IF(OR(H38>0,J38>0),"เพิ่มขึ้น","คงเดิม")) | O38: =IF(ISBLANK(B38),"",IF(LEN(B38)=13,IF(RIGHT(11-MOD(MID(B38,1,1)*13+MID(B38,2,1)*12+MID(B38,3,1)*11+MID(B38,4,1)*10+MID(B38,5,1)*9+MID(B38,6,1)*8+MID(B38,7,1)*7+MID(B38,8,1)*6+MID(B38,9,1)*5+MID(B38,10,1)*4+MID(B38,11,1)*3+MID(B38,12,1)*2,11))=RIGHT(B38),"ถูกต้อง","ผิด "),"ไม่ครบ13หลัก")) | P38: =CONCATENATE(D38," ",E38) | AH38: E 38 การเก็บรวบรวมของเสีย การบำบัดและการกำจัดของเสีย การนำของเสียกลับมาใช้ใหม่
L39: =IF(ISBLANK(B39),"",IF(SUM(G39:K39)>0,"เพิ่มขึ้น","คงเดิม")) | M39: =IF(ISBLANK(B39),"",IF(OR(H39>0,J39>0),"เพิ่มขึ้น","คงเดิม")) | O39: =IF(ISBLANK(B39),"",IF(LEN(B39)=13,IF(RIGHT(11-MOD(MID(B39,1,1)*13+MID(B39,2,1)*12+MID(B39,3,1)*11+MID(B39,4,1)*10+MID(B39,5,1)*9+MID(B39,6,1)*8+MID(B39,7,1)*7+MID(B39,8,1)*6+MID(B39,9,1)*5+MID(B39,10,1)*4+MID(B39,11,1)*3+MID(B39,12,1)*2,11))=RIGHT(B39),"ถูกต้อง","ผิด "),"ไม่ครบ13หลัก")) | P39: =CONCATENATE(D39," ",E39) | AH39: E 39 กิจกรรมการบำบัด และการจัดบริการเก็บของเสียอื่น ๆ
L40: =IF(ISBLANK(B40),"",IF(SUM(G40:K40)>0,"เพิ่มขึ้น","คงเดิม")) | M40: =IF(ISBLANK(B40),"",IF(OR(H40>0,J40>0),"เพิ่มขึ้น","คงเดิม")) | O40: =IF(ISBLANK(B40),"",IF(LEN(B40)=13,IF(RIGHT(11-MOD(MID(B40,1,1)*13+MID(B40,2,1)*12+MID(B40,3,1)*11+MID(B40,4,1)*10+MID(B40,5,1)*9+MID(B40,6,1)*8+MID(B40,7,1)*7+MID(B40,8,1)*6+MID(B40,9,1)*5+MID(B40,10,1)*4+MID(B40,11,1)*3+MID(B40,12,1)*2,11))=RIGHT(B40),"ถูกต้อง","ผิด "),"ไม่ครบ13หลัก")) | P40: =CONCATENATE(D40," ",E40) | AH40: F 41 การก่อสร้างอาคาร
L41: =IF(ISBLANK(B41),"",IF(SUM(G41:K41)>0,"เพิ่มขึ้น","คงเดิม")) | M41: =IF(ISBLANK(B41),"",IF(OR(H41>0,J41>0),"เพิ่มขึ้น","คงเดิม")) | O41: =IF(ISBLANK(B41),"",IF(LEN(B41)=13,IF(RIGHT(11-MOD(MID(B41,1,1)*13+MID(B41,2,1)*12+MID(B41,3,1)*11+MID(B41,4,1)*10+MID(B41,5,1)*9+MID(B41,6,1)*8+MID(B41,7,1)*7+MID(B41,8,1)*6+MID(B41,9,1)*5+MID(B41,10,1)*4+MID(B41,11,1)*3+MID(B41,12,1)*2,11))=RIGHT(B41),"ถูกต้อง","ผิด "),"ไม่ครบ13หลัก")) | P41: =CONCATENATE(D41," ",E41) | AH41: F 42 งานวิศวกรรมโยธา
...

Sheet Data
A1: PERSON_ID | B1: TITLE | C1: FIRSTNAME | D1: LASTNAME | E1: GENDER | F1: POSITION | G1: STATUS | H1: REMARK | I1: ตรวจสอบ Personal_ID | J1: ชีทนี้ สำหรับเจ้าหน้าที่ กรมพัฒนาฝีมือแรงงาน
A2: =IF(ISBLANK(Summary!B8),"",Summary!B8) -> 999999999 | B2: =IF(ISBLANK(Summary!B8),"",Summary!C8) -> นาย | C2: =IF(ISBLANK(Summary!B8),"",Summary!D8) -> เสริฐสินธ์ | D2: =IF(ISBLANK(Summary!B8),"",Summary!E8) -> ธัญญรังสิกุล | E2: =IF(ISBLANK(Summary!B8),"",IF(TRIM(SUBSTITUTE(B2," ",""))="นาย","ชาย",IF(TRIM(SUBSTITUTE(B2," ",""))="นาง","หญิง",IF(TRIM(SUBSTITUTE(B2," ",""))="นางสาว","หญิง",IF(TRIM(SUBSTITUTE(B2," ",""))="น.ส.","หญิง","ระบุคำนำหน้าใม่ถูก"))))) -> ชาย | F2: =IF(ISBLANK(Summary!B8),"",Summary!F8) -> หัวหน้างานขายสินค้าทางโทรศัพท์ | G2: =IF(ISBLANK(Summary!B8),"",IF(Summary!Q8="passed","ผ่าน",IF(Summary!Q8="fail","ไม่ผ่าน",""))) | H2: =IF(ISBLANK(Summary!B8),"",CONCATENATE(Summary!G8,Summary!H8,Summary!I8,Summary!J8,Summary!K8,N2)) -> 111101 | I2: =IF(ISBLANK(Summary!B8),"",IF(LEN(A2)=13,IF(RIGHT(11-MOD(MID(A2,1,1)*13+MID(A2,2,1)*12+MID(A2,3,1)*11+MID(A2,4,1)*10+MID(A2,5,1)*9+MID(A2,6,1)*8+MID(A2,7,1)*7+MID(A2,8,1)*6+MID(A2,9,1)*5+MID(A2,10,1)*4+MID(A2,11,1)*3+MID(A2,12,1)*2,11))=RIGHT(A2),"ถูกต้อง","ผิด "),"ไม่ครบ13หลัก")) -> ไม่ครบ13หลัก | L2: =Summary!N8 -> less than 10,000 (น้อยกว่า 10,000) | N2: =IF(L2="less than 10,000 (น้อยกว่า 10,000)",1,IF(L2="10,001-20,000",2,IF(L2="20,001-30,000",3,IF(L2="30,001-40,000",4,IF(L2="40,001-50,000",5,IF(L2="more than 50,001 (มากกว่า 50,001)",6,7)))))) -> 1
A3: =IF(ISBLANK(Summary!B9),"",Summary!B9) -> 123232323233 | B3: =IF(ISBLANK(Summary!B9),"",Summary!C9) -> นาย | C3: =IF(ISBLANK(Summary!B9),"",Summary!D9) -> โกสินทร์ | D3: =IF(ISBLANK(Summary!B9),"",Summary!E9) -> วุฒิเจริญวงศ์ | E3: =IF(ISBLANK(Summary!B9),"",IF(TRIM(SUBSTITUTE(B3," ",""))="นาย","ชาย",IF(TRIM(SUBSTITUTE(B3," ",""))="นาง","หญิง",IF(TRIM(SUBSTITUTE(B3," ",""))="นางสาว","หญิง",IF(TRIM(SUBSTITUTE(B3," ",""))="น.ส.","หญิง","ระบุคำนำหน้าใม่ถูก"))))) -> ชาย | F3: =IF(ISBLANK(Summary!B9),"",Summary!F9) -> กรรมการผู้จัดการ | G3: =IF(ISBLANK(Summary!B9),"",IF(Summary!Q9="passed","ผ่าน",IF(Summary!Q9="fail","ไม่ผ่าน",""))) | H3: =IF(ISBLANK(Summary!B9),"",CONCATENATE(Summary!G9,Summary!H9,Summary!I9,Summary!J9,Summary!K9,N3)) -> 010101 | I3: =IF(ISBLANK(Summary!B9),"",IF(LEN(A3)=13,IF(RIGHT(11-MOD(MID(A3,1,1)*13+MID(A3,2,1)*12+MID(A3,3,1)*11+MID(A3,4,1)*10+MID(A3,5,1)*9+MID(A3,6,1)*8+MID(A3,7,1)*7+MID(A3,8,1)*6+MID(A3,9,1)*5+MID(A3,10,1)*4+MID(A3,11,1)*3+MID(A3,12,1)*2,11))=RIGHT(A3),"ถูกต้อง","ผิด "),"ไม่ครบ13หลัก")) -> ไม่ครบ13หลัก | L3: =Summary!N9 -> less than 10,000 (น้อยกว่า 10,000) | N3: =IF(L3="less than 10,000 (น้อยกว่า 10,000)",1,IF(L3="10,001-20,000",2,IF(L3="20,001-30,000",3,IF(L3="30,001-40,000",4,IF(L3="40,001-50,000",5,IF(L3="more than 50,001 (มากกว่า 50,001)",6,7)))))) -> 1
A4: =IF(ISBLANK(Summary!B10),"",Summary!B10) -> 6565656565656 | B4: =IF(ISBLANK(Summary!B10),"",Summary!C10) -> นางสาว | C4: =IF(ISBLANK(Summary!B10),"",Summary!D10) -> กันยารัตน์ | D4: =IF(ISBLANK(Summary!B10),"",Summary!E10) -> ดีประเสริฐ | E4: =IF(ISBLANK(Summary!B10),"",IF(TRIM(SUBSTITUTE(B4," ",""))="นาย","ชาย",IF(TRIM(SUBSTITUTE(B4," ",""))="นาง","หญิง",IF(TRIM(SUBSTITUTE(B4," ",""))="นางสาว","หญิง",IF(TRIM(SUBSTITUTE(B4," ",""))="น.ส.","หญิง","ระบุคำนำหน้าใม่ถูก"))))) -> หญิง | F4: =IF(ISBLANK(Summary!B10),"",Summary!F10) -> ผู้เชี่ยวชาญงานสนับสนุนธุรกิจและประสบการณ์ลูกค้า | G4: =IF(ISBLANK(Summary!B10),"",IF(Summary!Q10="passed","ผ่าน",IF(Summary!Q10="fail","ไม่ผ่าน",""))) | H4: =IF(ISBLANK(Summary!B10),"",CONCATENATE(Summary!G10,Summary!H10,Summary!I10,Summary!J10,Summary!K10,N4)) -> 010101 | I4: =IF(ISBLANK(Summary!B10),"",IF(LEN(A4)=13,IF(RIGHT(11-MOD(MID(A4,1,1)*13+MID(A4,2,1)*12+MID(A4,3,1)*11+MID(A4,4,1)*10+MID(A4,5,1)*9+MID(A4,6,1)*8+MID(A4,7,1)*7+MID(A4,8,1)*6+MID(A4,9,1)*5+MID(A4,10,1)*4+MID(A4,11,1)*3+MID(A4,12,1)*2,11))=RIGHT(A4),"ถูกต้อง","ผิด "),"ไม่ครบ13หลัก")) -> ผิด | L4: =Summary!N10 -> less than 10,000 (น้อยกว่า 10,000) | N4: =IF(L4="less than 10,000 (น้อยกว่า 10,000)",1,IF(L4="10,001-20,000",2,IF(L4="20,001-30,000",3,IF(L4="30,001-40,000",4,IF(L4="40,001-50,000",5,IF(L4="more than 50,001 (มากกว่า 50,001)",6,7)))))) -> 1
A5: =IF(ISBLANK(Summary!B11),"",Summary!B11) -> 777777777 | B5: =IF(ISBLANK(Summary!B11),"",Summary!C11) -> นาย | C5: =IF(ISBLANK(Summary!B11),"",Summary!D11) -> จักรกฤษณ์ | D5: =IF(ISBLANK(Summary!B11),"",Summary!E11) -> กำบังกาย | E5: =IF(ISBLANK(Summary!B11),"",IF(TRIM(SUBSTITUTE(B5," ",""))="นาย","ชาย",IF(TRIM(SUBSTITUTE(B5," ",""))="นาง","หญิง",IF(TRIM(SUBSTITUTE(B5," ",""))="นางสาว","หญิง",IF(TRIM(SUBSTITUTE(B5," ",""))="น.ส.","หญิง","ระบุคำนำหน้าใม่ถูก"))))) -> ชาย | F5: =IF(ISBLANK(Summary!B11),"",Summary!F11) -> หัวหน้าทีมวิเคราะห์ข้อมูลและเทคโนโลยีดิจิทัล | G5: =IF(ISBLANK(Summary!B11),"",IF(Summary!Q11="passed","ผ่าน",IF(Summary!Q11="fail","ไม่ผ่าน",""))) | H5: =IF(ISBLANK(Summary!B11),"",CONCATENATE(Summary!G11,Summary!H11,Summary!I11,Summary!J11,Summary!K11,N5)) -> 112102 | I5: =IF(ISBLANK(Summary!B11),"",IF(LEN(A5)=13,IF(RIGHT(11-MOD(MID(A5,1,1)*13+MID(A5,2,1)*12+MID(A5,3,1)*11+MID(A5,4,1)*10+MID(A5,5,1)*9+MID(A5,6,1)*8+MID(A5,7,1)*7+MID(A5,8,1)*6+MID(A5,9,1)*5+MID(A5,10,1)*4+MID(A5,11,1)*3+MID(A5,12,1)*2,11))=RIGHT(A5),"ถูกต้อง","ผิด "),"ไม่ครบ13หลัก")) -> ไม่ครบ13หลัก | L5: =Summary!N11 -> 10,001-20,000 | M5: ชาย | N5: =IF(L5="less than 10,000 (น้อยกว่า 10,000)",1,IF(L5="10,001-20,000",2,IF(L5="20,001-30,000",3,IF(L5="30,001-40,000",4,IF(L5="40,001-50,000",5,IF(L5="more than 50,001 (มากกว่า 50,001)",6,7)))))) -> 2
A6: =IF(ISBLANK(Summary!B12),"",Summary!B12) -> 88888888 | B6: =IF(ISBLANK(Summary!B12),"",Summary!C12) -> นาย | C6: =IF(ISBLANK(Summary!B12),"",Summary!D12) -> ชัยเมศร์ | D6: =IF(ISBLANK(Summary!B12),"",Summary!E12) -> วรสมบูรณ์ไชย | E6: =IF(ISBLANK(Summary!B12),"",IF(TRIM(SUBSTITUTE(B6," ",""))="นาย","ชาย",IF(TRIM(SUBSTITUTE(B6," ",""))="นาง","หญิง",IF(TRIM(SUBSTITUTE(B6," ",""))="นางสาว","หญิง",IF(TRIM(SUBSTITUTE(B6," ",""))="น.ส.","หญิง","ระบุคำนำหน้าใม่ถูก"))))) -> ชาย | F6: =IF(ISBLANK(Summary!B12),"",Summary!F12) -> หัวหน้างานขายสินค้าทางโทรศัพท์ | G6: =IF(ISBLANK(Summary!B12),"",IF(Summary!Q12="passed","ผ่าน",IF(Summary!Q12="fail","ไม่ผ่าน",""))) | H6: =IF(ISBLANK(Summary!B12),"",CONCATENATE(Summary!G12,Summary!H12,Summary!I12,Summary!J12,Summary!K12,N6)) -> 112104 | I6: =IF(ISBLANK(Summary!B12),"",IF(LEN(A6)=13,IF(RIGHT(11-MOD(MID(A6,1,1)*13+MID(A6,2,1)*12+MID(A6,3,1)*11+MID(A6,4,1)*10+MID(A6,5,1)*9+MID(A6,6,1)*8+MID(A6,7,1)*7+MID(A6,8,1)*6+MID(A6,9,1)*5+MID(A6,10,1)*4+MID(A6,11,1)*3+MID(A6,12,1)*2,11))=RIGHT(A6),"ถูกต้อง","ผิด "),"ไม่ครบ13หลัก")) -> ไม่ครบ13หลัก | L6: =Summary!N12 -> 30,001-40,000 | M6: หญิง | N6: =IF(L6="less than 10,000 (น้อยกว่า 10,000)",1,IF(L6="10,001-20,000",2,IF(L6="20,001-30,000",3,IF(L6="30,001-40,000",4,IF(L6="40,001-50,000",5,IF(L6="more than 50,001 (มากกว่า 50,001)",6,7)))))) -> 4
A7: =IF(ISBLANK(Summary!B13),"",Summary!B13) -> 999999999 | B7: =IF(ISBLANK(Summary!B13),"",Summary!C13) -> นางสาว | C7: =IF(ISBLANK(Summary!B13),"",Summary!D13) -> ฐายิกา | D7: =IF(ISBLANK(Summary!B13),"",Summary!E13) -> ทัศนีย์ | E7: =IF(ISBLANK(Summary!B13),"",IF(TRIM(SUBSTITUTE(B7," ",""))="นาย","ชาย",IF(TRIM(SUBSTITUTE(B7," ",""))="นาง","หญิง",IF(TRIM(SUBSTITUTE(B7," ",""))="นางสาว","หญิง",IF(TRIM(SUBSTITUTE(B7," ",""))="น.ส.","หญิง","ระบุคำนำหน้าใม่ถูก"))))) -> หญิง | F7: =IF(ISBLANK(Summary!B13),"",Summary!F13) -> พนักงานบริการหลังการขาย | G7: =IF(ISBLANK(Summary!B13),"",IF(Summary!Q13="passed","ผ่าน",IF(Summary!Q13="fail","ไม่ผ่าน",""))) | H7: =IF(ISBLANK(Summary!B13),"",CONCATENATE(Summary!G13,Summary!H13,Summary!I13,Summary!J13,Summary!K13,N7)) -> 111102 | I7: =IF(ISBLANK(Summary!B13),"",IF(LEN(A7)=13,IF(RIGHT(11-MOD(MID(A7,1,1)*13+MID(A7,2,1)*12+MID(A7,3,1)*11+MID(A7,4,1)*10+MID(A7,5,1)*9+MID(A7,6,1)*8+MID(A7,7,1)*7+MID(A7,8,1)*6+MID(A7,9,1)*5+MID(A7,10,1)*4+MID(A7,11,1)*3+MID(A7,12,1)*2,11))=RIGHT(A7),"ถูกต้อง","ผิด "),"ไม่ครบ13หลัก")) -> ไม่ครบ13หลัก | L7: =Summary!N13 -> 10,001-20,000 | N7: =IF(L7="less than 10,000 (น้อยกว่า 10,000)",1,IF(L7="10,001-20,000",2,IF(L7="20,001-30,000",3,IF(L7="30,001-40,000",4,IF(L7="40,001-50,000",5,IF(L7="more than 50,001 (มากกว่า 50,001)",6,7)))))) -> 2
A8: =IF(ISBLANK(Summary!B14),"",Summary!B14) | B8: =IF(ISBLANK(Summary!B14),"",Summary!C14) | C8: =IF(ISBLANK(Summary!B14),"",Summary!D14) | D8: =IF(ISBLANK(Summary!B14),"",Summary!E14) | E8: =IF(ISBLANK(Summary!B14),"",IF(TRIM(SUBSTITUTE(B8," ",""))="นาย","ชาย",IF(TRIM(SUBSTITUTE(B8," ",""))="นาง","หญิง",IF(TRIM(SUBSTITUTE(B8," ",""))="นางสาว","หญิง",IF(TRIM(SUBSTITUTE(B8," ",""))="น.ส.","หญิง","ระบุคำนำหน้าใม่ถูก"))))) | F8: =IF(ISBLANK(Summary!B14),"",Summary!F14) | G8: =IF(ISBLANK(Summary!B14),"",IF(Summary!Q14="passed","ผ่าน",IF(Summary!Q14="fail","ไม่ผ่าน",""))) | H8: =IF(ISBLANK(Summary!B14),"",CONCATENATE(Summary!G14,Summary!H14,Summary!I14,Summary!J14,Summary!K14,N8)) | I8: =IF(ISBLANK(Summary!B14),"",IF(LEN(A8)=13,IF(RIGHT(11-MOD(MID(A8,1,1)*13+MID(A8,2,1)*12+MID(A8,3,1)*11+MID(A8,4,1)*10+MID(A8,5,1)*9+MID(A8,6,1)*8+MID(A8,7,1)*7+MID(A8,8,1)*6+MID(A8,9,1)*5+MID(A8,10,1)*4+MID(A8,11,1)*3+MID(A8,12,1)*2,11))=RIGHT(A8),"ถูกต้อง","ผิด "),"ไม่ครบ13หลัก")) | L8: =Summary!N14 -> 0 | N8: =IF(L8="less than 10,000 (น้อยกว่า 10,000)",1,IF(L8="10,001-20,000",2,IF(L8="20,001-30,000",3,IF(L8="30,001-40,000",4,IF(L8="40,001-50,000",5,IF(L8="more than 50,001 (มากกว่า 50,001)",6,7)))))) -> 7
A9: =IF(ISBLANK(Summary!B15),"",Summary!B15) | B9: =IF(ISBLANK(Summary!B15),"",Summary!C15) | C9: =IF(ISBLANK(Summary!B15),"",Summary!D15) | D9: =IF(ISBLANK(Summary!B15),"",Summary!E15) | E9: =IF(ISBLANK(Summary!B15),"",IF(TRIM(SUBSTITUTE(B9," ",""))="นาย","ชาย",IF(TRIM(SUBSTITUTE(B9," ",""))="นาง","หญิง",IF(TRIM(SUBSTITUTE(B9," ",""))="นางสาว","หญิง",IF(TRIM(SUBSTITUTE(B9," ",""))="น.ส.","หญิง","ระบุคำนำหน้าใม่ถูก"))))) | F9: =IF(ISBLANK(Summary!B15),"",Summary!F15) | G9: =IF(ISBLANK(Summary!B15),"",IF(Summary!Q15="passed","ผ่าน",IF(Summary!Q15="fail","ไม่ผ่าน",""))) | H9: =IF(ISBLANK(Summary!B15),"",CONCATENATE(Summary!G15,Summary!H15,Summary!I15,Summary!J15,Summary!K15,N9)) | I9: =IF(ISBLANK(Summary!B15),"",IF(LEN(A9)=13,IF(RIGHT(11-MOD(MID(A9,1,1)*13+MID(A9,2,1)*12+MID(A9,3,1)*11+MID(A9,4,1)*10+MID(A9,5,1)*9+MID(A9,6,1)*8+MID(A9,7,1)*7+MID(A9,8,1)*6+MID(A9,9,1)*5+MID(A9,10,1)*4+MID(A9,11,1)*3+MID(A9,12,1)*2,11))=RIGHT(A9),"ถูกต้อง","ผิด "),"ไม่ครบ13หลัก")) | J9: รวมชาย | L9: =Summary!N15 -> 0 | N9: =IF(L9="less than 10,000 (น้อยกว่า 10,000)",1,IF(L9="10,001-20,000",2,IF(L9="20,001-30,000",3,IF(L9="30,001-40,000",4,IF(L9="40,001-50,000",5,IF(L9="more than 50,001 (มากกว่า 50,001)",6,7)))))) -> 7
A10: =IF(ISBLANK(Summary!B16),"",Summary!B16) | B10: =IF(ISBLANK(Summary!B16),"",Summary!C16) | C10: =IF(ISBLANK(Summary!B16),"",Summary!D16) | D10: =IF(ISBLANK(Summary!B16),"",Summary!E16) | E10: =IF(ISBLANK(Summary!B16),"",IF(TRIM(SUBSTITUTE(B10," ",""))="นาย","ชาย",IF(TRIM(SUBSTITUTE(B10," ",""))="นาง","หญิง",IF(TRIM(SUBSTITUTE(B10," ",""))="นางสาว","หญิง",IF(TRIM(SUBSTITUTE(B10," ",""))="น.ส.","หญิง","ระบุคำนำหน้าใม่ถูก"))))) | F10: =IF(ISBLANK(Summary!B16),"",Summary!F16) | G10: =IF(ISBLANK(Summary!B16),"",IF(Summary!Q16="passed","ผ่าน",IF(Summary!Q16="fail","ไม่ผ่าน",""))) | H10: =IF(ISBLANK(Summary!B16),"",CONCATENATE(Summary!G16,Summary!H16,Summary!I16,Summary!J16,Summary!K16,N10)) | I10: =IF(ISBLANK(Summary!B16),"",IF(LEN(A10)=13,IF(RIGHT(11-MOD(MID(A10,1,1)*13+MID(A10,2,1)*12+MID(A10,3,1)*11+MID(A10,4,1)*10+MID(A10,5,1)*9+MID(A10,6,1)*8+MID(A10,7,1)*7+MID(A10,8,1)*6+MID(A10,9,1)*5+MID(A10,10,1)*4+MID(A10,11,1)*3+MID(A10,12,1)*2,11))=RIGHT(A10),"ถูกต้อง","ผิด "),"ไม่ครบ13หลัก")) | J10: =COUNTIF(E2:E101,"ชาย") -> 4 | L10: =Summary!N16 -> 0 | N10: =IF(L10="less than 10,000 (น้อยกว่า 10,000)",1,IF(L10="10,001-20,000",2,IF(L10="20,001-30,000",3,IF(L10="30,001-40,000",4,IF(L10="40,001-50,000",5,IF(L10="more than 50,001 (มากกว่า 50,001)",6,7)))))) -> 7
A11: =IF(ISBLANK(Summary!B17),"",Summary!B17) | B11: =IF(ISBLANK(Summary!B17),"",Summary!C17) | C11: =IF(ISBLANK(Summary!B17),"",Summary!D17) | D11: =IF(ISBLANK(Summary!B17),"",Summary!E17) | E11: =IF(ISBLANK(Summary!B17),"",IF(TRIM(SUBSTITUTE(B11," ",""))="นาย","ชาย",IF(TRIM(SUBSTITUTE(B11," ",""))="นาง","หญิง",IF(TRIM(SUBSTITUTE(B11," ",""))="นางสาว","หญิง",IF(TRIM(SUBSTITUTE(B11," ",""))="น.ส.","หญิง","ระบุคำนำหน้าใม่ถูก"))))) | F11: =IF(ISBLANK(Summary!B17),"",Summary!F17) | G11: =IF(ISBLANK(Summary!B17),"",IF(Summary!Q17="passed","ผ่าน",IF(Summary!Q17="fail","ไม่ผ่าน",""))) | H11: =IF(ISBLANK(Summary!B17),"",CONCATENATE(Summary!G17,Summary!H17,Summary!I17,Summary!J17,Summary!K17,N11)) | I11: =IF(ISBLANK(Summary!B17),"",IF(LEN(A11)=13,IF(RIGHT(11-MOD(MID(A11,1,1)*13+MID(A11,2,1)*12+MID(A11,3,1)*11+MID(A11,4,1)*10+MID(A11,5,1)*9+MID(A11,6,1)*8+MID(A11,7,1)*7+MID(A11,8,1)*6+MID(A11,9,1)*5+MID(A11,10,1)*4+MID(A11,11,1)*3+MID(A11,12,1)*2,11))=RIGHT(A11),"ถูกต้อง","ผิด "),"ไม่ครบ13หลัก")) | J11: รวมหญิง | L11: =Summary!N17 -> 0 | N11: =IF(L11="less than 10,000 (น้อยกว่า 10,000)",1,IF(L11="10,001-20,000",2,IF(L11="20,001-30,000",3,IF(L11="30,001-40,000",4,IF(L11="40,001-50,000",5,IF(L11="more than 50,001 (มากกว่า 50,001)",6,7)))))) -> 7
A12: =IF(ISBLANK(Summary!B18),"",Summary!B18) | B12: =IF(ISBLANK(Summary!B18),"",Summary!C18) | C12: =IF(ISBLANK(Summary!B18),"",Summary!D18) | D12: =IF(ISBLANK(Summary!B18),"",Summary!E18) | E12: =IF(ISBLANK(Summary!B18),"",IF(TRIM(SUBSTITUTE(B12," ",""))="นาย","ชาย",IF(TRIM(SUBSTITUTE(B12," ",""))="นาง","หญิง",IF(TRIM(SUBSTITUTE(B12," ",""))="นางสาว","หญิง",IF(TRIM(SUBSTITUTE(B12," ",""))="น.ส.","หญิง","ระบุคำนำหน้าใม่ถูก"))))) | F12: =IF(ISBLANK(Summary!B18),"",Summary!F18) | G12: =IF(ISBLANK(Summary!B18),"",IF(Summary!Q18="passed","ผ่าน",IF(Summary!Q18="fail","ไม่ผ่าน",""))) | H12: =IF(ISBLANK(Summary!B18),"",CONCATENATE(Summary!G18,Summary!H18,Summary!I18,Summary!J18,Summary!K18,N12)) | I12: =IF(ISBLANK(Summary!B18),"",IF(LEN(A12)=13,IF(RIGHT(11-MOD(MID(A12,1,1)*13+MID(A12,2,1)*12+MID(A12,3,1)*11+MID(A12,4,1)*10+MID(A12,5,1)*9+MID(A12,6,1)*8+MID(A12,7,1)*7+MID(A12,8,1)*6+MID(A12,9,1)*5+MID(A12,10,1)*4+MID(A12,11,1)*3+MID(A12,12,1)*2,11))=RIGHT(A12),"ถูกต้อง","ผิด "),"ไม่ครบ13หลัก")) | J12: =COUNTIF(E2:E101,"หญิง") -> 2 | L12: =Summary!N18 -> 0 | N12: =IF(L12="less than 10,000 (น้อยกว่า 10,000)",1,IF(L12="10,001-20,000",2,IF(L12="20,001-30,000",3,IF(L12="30,001-40,000",4,IF(L12="40,001-50,000",5,IF(L12="more than 50,001 (มากกว่า 50,001)",6,7)))))) -> 7
A13: =IF(ISBLANK(Summary!B19),"",Summary!B19) | B13: =IF(ISBLANK(Summary!B19),"",Summary!C19) | C13: =IF(ISBLANK(Summary!B19),"",Summary!D19) | D13: =IF(ISBLANK(Summary!B19),"",Summary!E19) | E13: =IF(ISBLANK(Summary!B19),"",IF(TRIM(SUBSTITUTE(B13," ",""))="นาย","ชาย",IF(TRIM(SUBSTITUTE(B13," ",""))="นาง","หญิง",IF(TRIM(SUBSTITUTE(B13," ",""))="นางสาว","หญิง",IF(TRIM(SUBSTITUTE(B13," ",""))="น.ส.","หญิง","ระบุคำนำหน้าใม่ถูก"))))) | F13: =IF(ISBLANK(Summary!B19),"",Summary!F19) | G13: =IF(ISBLANK(Summary!B19),"",IF(Summary!Q19="passed","ผ่าน",IF(Summary!Q19="fail","ไม่ผ่าน",""))) | H13: =IF(ISBLANK(Summary!B19),"",CONCATENATE(Summary!G19,Summary!H19,Summary!I19,Summary!J19,Summary!K19,N13)) | I13: =IF(ISBLANK(Summary!B19),"",IF(LEN(A13)=13,IF(RIGHT(11-MOD(MID(A13,1,1)*13+MID(A13,2,1)*12+MID(A13,3,1)*11+MID(A13,4,1)*10+MID(A13,5,1)*9+MID(A13,6,1)*8+MID(A13,7,1)*7+MID(A13,8,1)*6+MID(A13,9,1)*5+MID(A13,10,1)*4+MID(A13,11,1)*3+MID(A13,12,1)*2,11))=RIGHT(A13),"ถูกต้อง","ผิด "),"ไม่ครบ13หลัก")) | J13: รวมทั้งสิ้น | L13: =Summary!N19 -> 0 | N13: =IF(L13="less than 10,000 (น้อยกว่า 10,000)",1,IF(L13="10,001-20,000",2,IF(L13="20,001-30,000",3,IF(L13="30,001-40,000",4,IF(L13="40,001-50,000",5,IF(L13="more than 50,001 (มากกว่า 50,001)",6,7)))))) -> 7
A14: =IF(ISBLANK(Summary!B20),"",Summary!B20) | B14: =IF(ISBLANK(Summary!B20),"",Summary!C20) | C14: =IF(ISBLANK(Summary!B20),"",Summary!D20) | D14: =IF(ISBLANK(Summary!B20),"",Summary!E20) | E14: =IF(ISBLANK(Summary!B20),"",IF(TRIM(SUBSTITUTE(B14," ",""))="นาย","ชาย",IF(TRIM(SUBSTITUTE(B14," ",""))="นาง","หญิง",IF(TRIM(SUBSTITUTE(B14," ",""))="นางสาว","หญิง",IF(TRIM(SUBSTITUTE(B14," ",""))="น.ส.","หญิง","ระบุคำนำหน้าใม่ถูก"))))) | F14: =IF(ISBLANK(Summary!B20),"",Summary!F20) | G14: =IF(ISBLANK(Summary!B20),"",IF(Summary!Q20="passed","ผ่าน",IF(Summary!Q20="fail","ไม่ผ่าน",""))) | H14: =IF(ISBLANK(Summary!B20),"",CONCATENATE(Summary!G20,Summary!H20,Summary!I20,Summary!J20,Summary!K20,N14)) | I14: =IF(ISBLANK(Summary!B20),"",IF(LEN(A14)=13,IF(RIGHT(11-MOD(MID(A14,1,1)*13+MID(A14,2,1)*12+MID(A14,3,1)*11+MID(A14,4,1)*10+MID(A14,5,1)*9+MID(A14,6,1)*8+MID(A14,7,1)*7+MID(A14,8,1)*6+MID(A14,9,1)*5+MID(A14,10,1)*4+MID(A14,11,1)*3+MID(A14,12,1)*2,11))=RIGHT(A14),"ถูกต้อง","ผิด "),"ไม่ครบ13หลัก")) | J14: =J10+J12 -> 6 | L14: =Summary!N20 -> 0 | N14: =IF(L14="less than 10,000 (น้อยกว่า 10,000)",1,IF(L14="10,001-20,000",2,IF(L14="20,001-30,000",3,IF(L14="30,001-40,000",4,IF(L14="40,001-50,000",5,IF(L14="more than 50,001 (มากกว่า 50,001)",6,7)))))) -> 7
A15: =IF(ISBLANK(Summary!B21),"",Summary!B21) | B15: =IF(ISBLANK(Summary!B21),"",Summary!C21) | C15: =IF(ISBLANK(Summary!B21),"",Summary!D21) | D15: =IF(ISBLANK(Summary!B21),"",Summary!E21) | E15: =IF(ISBLANK(Summary!B21),"",IF(TRIM(SUBSTITUTE(B15," ",""))="นาย","ชาย",IF(TRIM(SUBSTITUTE(B15," ",""))="นาง","หญิง",IF(TRIM(SUBSTITUTE(B15," ",""))="นางสาว","หญิง",IF(TRIM(SUBSTITUTE(B15," ",""))="น.ส.","หญิง","ระบุคำนำหน้าใม่ถูก"))))) | F15: =IF(ISBLANK(Summary!B21),"",Summary!F21) | G15: =IF(ISBLANK(Summary!B21),"",IF(Summary!Q21="passed","ผ่าน",IF(Summary!Q21="fail","ไม่ผ่าน",""))) | H15: =IF(ISBLANK(Summary!B21),"",CONCATENATE(Summary!G21,Summary!H21,Summary!I21,Summary!J21,Summary!K21,N15)) | I15: =IF(ISBLANK(Summary!B21),"",IF(LEN(A15)=13,IF(RIGHT(11-MOD(MID(A15,1,1)*13+MID(A15,2,1)*12+MID(A15,3,1)*11+MID(A15,4,1)*10+MID(A15,5,1)*9+MID(A15,6,1)*8+MID(A15,7,1)*7+MID(A15,8,1)*6+MID(A15,9,1)*5+MID(A15,10,1)*4+MID(A15,11,1)*3+MID(A15,12,1)*2,11))=RIGHT(A15),"ถูกต้อง","ผิด "),"ไม่ครบ13หลัก")) | L15: =Summary!N21 -> 0 | N15: =IF(L15="less than 10,000 (น้อยกว่า 10,000)",1,IF(L15="10,001-20,000",2,IF(L15="20,001-30,000",3,IF(L15="30,001-40,000",4,IF(L15="40,001-50,000",5,IF(L15="more than 50,001 (มากกว่า 50,001)",6,7)))))) -> 7
A16: =IF(ISBLANK(Summary!B22),"",Summary!B22) | B16: =IF(ISBLANK(Summary!B22),"",Summary!C22) | C16: =IF(ISBLANK(Summary!B22),"",Summary!D22) | D16: =IF(ISBLANK(Summary!B22),"",Summary!E22) | E16: =IF(ISBLANK(Summary!B22),"",IF(TRIM(SUBSTITUTE(B16," ",""))="นาย","ชาย",IF(TRIM(SUBSTITUTE(B16," ",""))="นาง","หญิง",IF(TRIM(SUBSTITUTE(B16," ",""))="นางสาว","หญิง",IF(TRIM(SUBSTITUTE(B16," ",""))="น.ส.","หญิง","ระบุคำนำหน้าใม่ถูก"))))) | F16: =IF(ISBLANK(Summary!B22),"",Summary!F22) | G16: =IF(ISBLANK(Summary!B22),"",IF(Summary!Q22="passed","ผ่าน",IF(Summary!Q22="fail","ไม่ผ่าน",""))) | H16: =IF(ISBLANK(Summary!B22),"",CONCATENATE(Summary!G22,Summary!H22,Summary!I22,Summary!J22,Summary!K22,N16)) | I16: =IF(ISBLANK(Summary!B22),"",IF(LEN(A16)=13,IF(RIGHT(11-MOD(MID(A16,1,1)*13+MID(A16,2,1)*12+MID(A16,3,1)*11+MID(A16,4,1)*10+MID(A16,5,1)*9+MID(A16,6,1)*8+MID(A16,7,1)*7+MID(A16,8,1)*6+MID(A16,9,1)*5+MID(A16,10,1)*4+MID(A16,11,1)*3+MID(A16,12,1)*2,11))=RIGHT(A16),"ถูกต้อง","ผิด "),"ไม่ครบ13หลัก")) | L16: =Summary!N22 -> 0 | N16: =IF(L16="less than 10,000 (น้อยกว่า 10,000)",1,IF(L16="10,001-20,000",2,IF(L16="20,001-30,000",3,IF(L16="30,001-40,000",4,IF(L16="40,001-50,000",5,IF(L16="more than 50,001 (มากกว่า 50,001)",6,7)))))) -> 7
A17: =IF(ISBLANK(Summary!B23),"",Summary!B23) | B17: =IF(ISBLANK(Summary!B23),"",Summary!C23) | C17: =IF(ISBLANK(Summary!B23),"",Summary!D23) | D17: =IF(ISBLANK(Summary!B23),"",Summary!E23) | E17: =IF(ISBLANK(Summary!B23),"",IF(TRIM(SUBSTITUTE(B17," ",""))="นาย","ชาย",IF(TRIM(SUBSTITUTE(B17," ",""))="นาง","หญิง",IF(TRIM(SUBSTITUTE(B17," ",""))="นางสาว","หญิง",IF(TRIM(SUBSTITUTE(B17," ",""))="น.ส.","หญิง","ระบุคำนำหน้าใม่ถูก"))))) | F17: =IF(ISBLANK(Summary!B23),"",Summary!F23) | G17: =IF(ISBLANK(Summary!B23),"",IF(Summary!Q23="passed","ผ่าน",IF(Summary!Q23="fail","ไม่ผ่าน",""))) | H17: =IF(ISBLANK(Summary!B23),"",CONCATENATE(Summary!G23,Summary!H23,Summary!I23,Summary!J23,Summary!K23,N17)) | I17: =IF(ISBLANK(Summary!B23),"",IF(LEN(A17)=13,IF(RIGHT(11-MOD(MID(A17,1,1)*13+MID(A17,2,1)*12+MID(A17,3,1)*11+MID(A17,4,1)*10+MID(A17,5,1)*9+MID(A17,6,1)*8+MID(A17,7,1)*7+MID(A17,8,1)*6+MID(A17,9,1)*5+MID(A17,10,1)*4+MID(A17,11,1)*3+MID(A17,12,1)*2,11))=RIGHT(A17),"ถูกต้อง","ผิด "),"ไม่ครบ13หลัก")) | L17: =Summary!N23 -> 0 | N17: =IF(L17="less than 10,000 (น้อยกว่า 10,000)",1,IF(L17="10,001-20,000",2,IF(L17="20,001-30,000",3,IF(L17="30,001-40,000",4,IF(L17="40,001-50,000",5,IF(L17="more than 50,001 (มากกว่า 50,001)",6,7)))))) -> 7
A18: =IF(ISBLANK(Summary!B24),"",Summary!B24) | B18: =IF(ISBLANK(Summary!B24),"",Summary!C24) | C18: =IF(ISBLANK(Summary!B24),"",Summary!D24) | D18: =IF(ISBLANK(Summary!B24),"",Summary!E24) | E18: =IF(ISBLANK(Summary!B24),"",IF(TRIM(SUBSTITUTE(B18," ",""))="นาย","ชาย",IF(TRIM(SUBSTITUTE(B18," ",""))="นาง","หญิง",IF(TRIM(SUBSTITUTE(B18," ",""))="นางสาว","หญิง",IF(TRIM(SUBSTITUTE(B18," ",""))="น.ส.","หญิง","ระบุคำนำหน้าใม่ถูก"))))) | F18: =IF(ISBLANK(Summary!B24),"",Summary!F24) | G18: =IF(ISBLANK(Summary!B24),"",IF(Summary!Q24="passed","ผ่าน",IF(Summary!Q24="fail","ไม่ผ่าน",""))) | H18: =IF(ISBLANK(Summary!B24),"",CONCATENATE(Summary!G24,Summary!H24,Summary!I24,Summary!J24,Summary!K24,N18)) | I18: =IF(ISBLANK(Summary!B24),"",IF(LEN(A18)=13,IF(RIGHT(11-MOD(MID(A18,1,1)*13+MID(A18,2,1)*12+MID(A18,3,1)*11+MID(A18,4,1)*10+MID(A18,5,1)*9+MID(A18,6,1)*8+MID(A18,7,1)*7+MID(A18,8,1)*6+MID(A18,9,1)*5+MID(A18,10,1)*4+MID(A18,11,1)*3+MID(A18,12,1)*2,11))=RIGHT(A18),"ถูกต้อง","ผิด "),"ไม่ครบ13หลัก")) | L18: =Summary!N24 -> 0 | N18: =IF(L18="less than 10,000 (น้อยกว่า 10,000)",1,IF(L18="10,001-20,000",2,IF(L18="20,001-30,000",3,IF(L18="30,001-40,000",4,IF(L18="40,001-50,000",5,IF(L18="more than 50,001 (มากกว่า 50,001)",6,7)))))) -> 7
A19: =IF(ISBLANK(Summary!B25),"",Summary!B25) | B19: =IF(ISBLANK(Summary!B25),"",Summary!C25) | C19: =IF(ISBLANK(Summary!B25),"",Summary!D25) | D19: =IF(ISBLANK(Summary!B25),"",Summary!E25) | E19: =IF(ISBLANK(Summary!B25),"",IF(TRIM(SUBSTITUTE(B19," ",""))="นาย","ชาย",IF(TRIM(SUBSTITUTE(B19," ",""))="นาง","หญิง",IF(TRIM(SUBSTITUTE(B19," ",""))="นางสาว","หญิง",IF(TRIM(SUBSTITUTE(B19," ",""))="น.ส.","หญิง","ระบุคำนำหน้าใม่ถูก"))))) | F19: =IF(ISBLANK(Summary!B25),"",Summary!F25) | G19: =IF(ISBLANK(Summary!B25),"",IF(Summary!Q25="passed","ผ่าน",IF(Summary!Q25="fail","ไม่ผ่าน",""))) | H19: =IF(ISBLANK(Summary!B25),"",CONCATENATE(Summary!G25,Summary!H25,Summary!I25,Summary!J25,Summary!K25,N19)) | I19: =IF(ISBLANK(Summary!B25),"",IF(LEN(A19)=13,IF(RIGHT(11-MOD(MID(A19,1,1)*13+MID(A19,2,1)*12+MID(A19,3,1)*11+MID(A19,4,1)*10+MID(A19,5,1)*9+MID(A19,6,1)*8+MID(A19,7,1)*7+MID(A19,8,1)*6+MID(A19,9,1)*5+MID(A19,10,1)*4+MID(A19,11,1)*3+MID(A19,12,1)*2,11))=RIGHT(A19),"ถูกต้อง","ผิด "),"ไม่ครบ13หลัก")) | L19: =Summary!N25 -> 0 | N19: =IF(L19="less than 10,000 (น้อยกว่า 10,000)",1,IF(L19="10,001-20,000",2,IF(L19="20,001-30,000",3,IF(L19="30,001-40,000",4,IF(L19="40,001-50,000",5,IF(L19="more than 50,001 (มากกว่า 50,001)",6,7)))))) -> 7
A20: =IF(ISBLANK(Summary!B26),"",Summary!B26) | B20: =IF(ISBLANK(Summary!B26),"",Summary!C26) | C20: =IF(ISBLANK(Summary!B26),"",Summary!D26) | D20: =IF(ISBLANK(Summary!B26),"",Summary!E26) | E20: =IF(ISBLANK(Summary!B26),"",IF(TRIM(SUBSTITUTE(B20," ",""))="นาย","ชาย",IF(TRIM(SUBSTITUTE(B20," ",""))="นาง","หญิง",IF(TRIM(SUBSTITUTE(B20," ",""))="นางสาว","หญิง",IF(TRIM(SUBSTITUTE(B20," ",""))="น.ส.","หญิง","ระบุคำนำหน้าใม่ถูก"))))) | F20: =IF(ISBLANK(Summary!B26),"",Summary!F26) | G20: =IF(ISBLANK(Summary!B26),"",IF(Summary!Q26="passed","ผ่าน",IF(Summary!Q26="fail","ไม่ผ่าน",""))) | H20: =IF(ISBLANK(Summary!B26),"",CONCATENATE(Summary!G26,Summary!H26,Summary!I26,Summary!J26,Summary!K26,N20)) | I20: =IF(ISBLANK(Summary!B26),"",IF(LEN(A20)=13,IF(RIGHT(11-MOD(MID(A20,1,1)*13+MID(A20,2,1)*12+MID(A20,3,1)*11+MID(A20,4,1)*10+MID(A20,5,1)*9+MID(A20,6,1)*8+MID(A20,7,1)*7+MID(A20,8,1)*6+MID(A20,9,1)*5+MID(A20,10,1)*4+MID(A20,11,1)*3+MID(A20,12,1)*2,11))=RIGHT(A20),"ถูกต้อง","ผิด "),"ไม่ครบ13หลัก")) | L20: =Summary!N26 -> 0 | N20: =IF(L20="less than 10,000 (น้อยกว่า 10,000)",1,IF(L20="10,001-20,000",2,IF(L20="20,001-30,000",3,IF(L20="30,001-40,000",4,IF(L20="40,001-50,000",5,IF(L20="more than 50,001 (มากกว่า 50,001)",6,7)))))) -> 7
A21: =IF(ISBLANK(Summary!B27),"",Summary!B27) | B21: =IF(ISBLANK(Summary!B27),"",Summary!C27) | C21: =IF(ISBLANK(Summary!B27),"",Summary!D27) | D21: =IF(ISBLANK(Summary!B27),"",Summary!E27) | E21: =IF(ISBLANK(Summary!B27),"",IF(TRIM(SUBSTITUTE(B21," ",""))="นาย","ชาย",IF(TRIM(SUBSTITUTE(B21," ",""))="นาง","หญิง",IF(TRIM(SUBSTITUTE(B21," ",""))="นางสาว","หญิง",IF(TRIM(SUBSTITUTE(B21," ",""))="น.ส.","หญิง","ระบุคำนำหน้าใม่ถูก"))))) | F21: =IF(ISBLANK(Summary!B27),"",Summary!F27) | G21: =IF(ISBLANK(Summary!B27),"",IF(Summary!Q27="passed","ผ่าน",IF(Summary!Q27="fail","ไม่ผ่าน",""))) | H21: =IF(ISBLANK(Summary!B27),"",CONCATENATE(Summary!G27,Summary!H27,Summary!I27,Summary!J27,Summary!K27,N21)) | I21: =IF(ISBLANK(Summary!B27),"",IF(LEN(A21)=13,IF(RIGHT(11-MOD(MID(A21,1,1)*13+MID(A21,2,1)*12+MID(A21,3,1)*11+MID(A21,4,1)*10+MID(A21,5,1)*9+MID(A21,6,1)*8+MID(A21,7,1)*7+MID(A21,8,1)*6+MID(A21,9,1)*5+MID(A21,10,1)*4+MID(A21,11,1)*3+MID(A21,12,1)*2,11))=RIGHT(A21),"ถูกต้อง","ผิด "),"ไม่ครบ13หลัก")) | L21: =Summary!N27 -> 0 | N21: =IF(L21="less than 10,000 (น้อยกว่า 10,000)",1,IF(L21="10,001-20,000",2,IF(L21="20,001-30,000",3,IF(L21="30,001-40,000",4,IF(L21="40,001-50,000",5,IF(L21="more than 50,001 (มากกว่า 50,001)",6,7)))))) -> 7
A22: =IF(ISBLANK(Summary!B28),"",Summary!B28) | B22: =IF(ISBLANK(Summary!B28),"",Summary!C28) | C22: =IF(ISBLANK(Summary!B28),"",Summary!D28) | D22: =IF(ISBLANK(Summary!B28),"",Summary!E28) | E22: =IF(ISBLANK(Summary!B28),"",IF(TRIM(SUBSTITUTE(B22," ",""))="นาย","ชาย",IF(TRIM(SUBSTITUTE(B22," ",""))="นาง","หญิง",IF(TRIM(SUBSTITUTE(B22," ",""))="นางสาว","หญิง",IF(TRIM(SUBSTITUTE(B22," ",""))="น.ส.","หญิง","ระบุคำนำหน้าใม่ถูก"))))) | F22: =IF(ISBLANK(Summary!B28),"",Summary!F28) | G22: =IF(ISBLANK(Summary!B28),"",IF(Summary!Q28="passed","ผ่าน",IF(Summary!Q28="fail","ไม่ผ่าน",""))) | H22: =IF(ISBLANK(Summary!B28),"",CONCATENATE(Summary!G28,Summary!H28,Summary!I28,Summary!J28,Summary!K28,N22)) | I22: =IF(ISBLANK(Summary!B28),"",IF(LEN(A22)=13,IF(RIGHT(11-MOD(MID(A22,1,1)*13+MID(A22,2,1)*12+MID(A22,3,1)*11+MID(A22,4,1)*10+MID(A22,5,1)*9+MID(A22,6,1)*8+MID(A22,7,1)*7+MID(A22,8,1)*6+MID(A22,9,1)*5+MID(A22,10,1)*4+MID(A22,11,1)*3+MID(A22,12,1)*2,11))=RIGHT(A22),"ถูกต้อง","ผิด "),"ไม่ครบ13หลัก")) | L22: =Summary!N28 -> 0 | N22: =IF(L22="less than 10,000 (น้อยกว่า 10,000)",1,IF(L22="10,001-20,000",2,IF(L22="20,001-30,000",3,IF(L22="30,001-40,000",4,IF(L22="40,001-50,000",5,IF(L22="more than 50,001 (มากกว่า 50,001)",6,7)))))) -> 7
A23: =IF(ISBLANK(Summary!B29),"",Summary!B29) | B23: =IF(ISBLANK(Summary!B29),"",Summary!C29) | C23: =IF(ISBLANK(Summary!B29),"",Summary!D29) | D23: =IF(ISBLANK(Summary!B29),"",Summary!E29) | E23: =IF(ISBLANK(Summary!B29),"",IF(TRIM(SUBSTITUTE(B23," ",""))="นาย","ชาย",IF(TRIM(SUBSTITUTE(B23," ",""))="นาง","หญิง",IF(TRIM(SUBSTITUTE(B23," ",""))="นางสาว","หญิง",IF(TRIM(SUBSTITUTE(B23," ",""))="น.ส.","หญิง","ระบุคำนำหน้าใม่ถูก"))))) | F23: =IF(ISBLANK(Summary!B29),"",Summary!F29) | G23: =IF(ISBLANK(Summary!B29),"",IF(Summary!Q29="passed","ผ่าน",IF(Summary!Q29="fail","ไม่ผ่าน",""))) | H23: =IF(ISBLANK(Summary!B29),"",CONCATENATE(Summary!G29,Summary!H29,Summary!I29,Summary!J29,Summary!K29,N23)) | I23: =IF(ISBLANK(Summary!B29),"",IF(LEN(A23)=13,IF(RIGHT(11-MOD(MID(A23,1,1)*13+MID(A23,2,1)*12+MID(A23,3,1)*11+MID(A23,4,1)*10+MID(A23,5,1)*9+MID(A23,6,1)*8+MID(A23,7,1)*7+MID(A23,8,1)*6+MID(A23,9,1)*5+MID(A23,10,1)*4+MID(A23,11,1)*3+MID(A23,12,1)*2,11))=RIGHT(A23),"ถูกต้อง","ผิด "),"ไม่ครบ13หลัก")) | L23: =Summary!N29 -> 0 | N23: =IF(L23="less than 10,000 (น้อยกว่า 10,000)",1,IF(L23="10,001-20,000",2,IF(L23="20,001-30,000",3,IF(L23="30,001-40,000",4,IF(L23="40,001-50,000",5,IF(L23="more than 50,001 (มากกว่า 50,001)",6,7)))))) -> 7
A24: =IF(ISBLANK(Summary!B30),"",Summary!B30) | B24: =IF(ISBLANK(Summary!B30),"",Summary!C30) | C24: =IF(ISBLANK(Summary!B30),"",Summary!D30) | D24: =IF(ISBLANK(Summary!B30),"",Summary!E30) | E24: =IF(ISBLANK(Summary!B30),"",IF(TRIM(SUBSTITUTE(B24," ",""))="นาย","ชาย",IF(TRIM(SUBSTITUTE(B24," ",""))="นาง","หญิง",IF(TRIM(SUBSTITUTE(B24," ",""))="นางสาว","หญิง",IF(TRIM(SUBSTITUTE(B24," ",""))="น.ส.","หญิง","ระบุคำนำหน้าใม่ถูก"))))) | F24: =IF(ISBLANK(Summary!B30),"",Summary!F30) | G24: =IF(ISBLANK(Summary!B30),"",IF(Summary!Q30="passed","ผ่าน",IF(Summary!Q30="fail","ไม่ผ่าน",""))) | H24: =IF(ISBLANK(Summary!B30),"",CONCATENATE(Summary!G30,Summary!H30,Summary!I30,Summary!J30,Summary!K30,N24)) | I24: =IF(ISBLANK(Summary!B30),"",IF(LEN(A24)=13,IF(RIGHT(11-MOD(MID(A24,1,1)*13+MID(A24,2,1)*12+MID(A24,3,1)*11+MID(A24,4,1)*10+MID(A24,5,1)*9+MID(A24,6,1)*8+MID(A24,7,1)*7+MID(A24,8,1)*6+MID(A24,9,1)*5+MID(A24,10,1)*4+MID(A24,11,1)*3+MID(A24,12,1)*2,11))=RIGHT(A24),"ถูกต้อง","ผิด "),"ไม่ครบ13หลัก")) | L24: =Summary!N30 -> 0 | N24: =IF(L24="less than 10,000 (น้อยกว่า 10,000)",1,IF(L24="10,001-20,000",2,IF(L24="20,001-30,000",3,IF(L24="30,001-40,000",4,IF(L24="40,001-50,000",5,IF(L24="more than 50,001 (มากกว่า 50,001)",6,7)))))) -> 7
A25: =IF(ISBLANK(Summary!B31),"",Summary!B31) | B25: =IF(ISBLANK(Summary!B31),"",Summary!C31) | C25: =IF(ISBLANK(Summary!B31),"",Summary!D31) | D25: =IF(ISBLANK(Summary!B31),"",Summary!E31) | E25: =IF(ISBLANK(Summary!B31),"",IF(TRIM(SUBSTITUTE(B25," ",""))="นาย","ชาย",IF(TRIM(SUBSTITUTE(B25," ",""))="นาง","หญิง",IF(TRIM(SUBSTITUTE(B25," ",""))="นางสาว","หญิง",IF(TRIM(SUBSTITUTE(B25," ",""))="น.ส.","หญิง","ระบุคำนำหน้าใม่ถูก"))))) | F25: =IF(ISBLANK(Summary!B31),"",Summary!F31) | G25: =IF(ISBLANK(Summary!B31),"",IF(Summary!Q31="passed","ผ่าน",IF(Summary!Q31="fail","ไม่ผ่าน",""))) | H25: =IF(ISBLANK(Summary!B31),"",CONCATENATE(Summary!G31,Summary!H31,Summary!I31,Summary!J31,Summary!K31,N25)) | I25: =IF(ISBLANK(Summary!B31),"",IF(LEN(A25)=13,IF(RIGHT(11-MOD(MID(A25,1,1)*13+MID(A25,2,1)*12+MID(A25,3,1)*11+MID(A25,4,1)*10+MID(A25,5,1)*9+MID(A25,6,1)*8+MID(A25,7,1)*7+MID(A25,8,1)*6+MID(A25,9,1)*5+MID(A25,10,1)*4+MID(A25,11,1)*3+MID(A25,12,1)*2,11))=RIGHT(A25),"ถูกต้อง","ผิด "),"ไม่ครบ13หลัก")) | L25: =Summary!N31 -> 0 | N25: =IF(L25="less than 10,000 (น้อยกว่า 10,000)",1,IF(L25="10,001-20,000",2,IF(L25="20,001-30,000",3,IF(L25="30,001-40,000",4,IF(L25="40,001-50,000",5,IF(L25="more than 50,001 (มากกว่า 50,001)",6,7)))))) -> 7
A26: =IF(ISBLANK(Summary!B32),"",Summary!B32) | B26: =IF(ISBLANK(Summary!B32),"",Summary!C32) | C26: =IF(ISBLANK(Summary!B32),"",Summary!D32) | D26: =IF(ISBLANK(Summary!B32),"",Summary!E32) | E26: =IF(ISBLANK(Summary!B32),"",IF(TRIM(SUBSTITUTE(B26," ",""))="นาย","ชาย",IF(TRIM(SUBSTITUTE(B26," ",""))="นาง","หญิง",IF(TRIM(SUBSTITUTE(B26," ",""))="นางสาว","หญิง",IF(TRIM(SUBSTITUTE(B26," ",""))="น.ส.","หญิง","ระบุคำนำหน้าใม่ถูก"))))) | F26: =IF(ISBLANK(Summary!B32),"",Summary!F32) | G26: =IF(ISBLANK(Summary!B32),"",IF(Summary!Q32="passed","ผ่าน",IF(Summary!Q32="fail","ไม่ผ่าน",""))) | H26: =IF(ISBLANK(Summary!B32),"",CONCATENATE(Summary!G32,Summary!H32,Summary!I32,Summary!J32,Summary!K32,N26)) | I26: =IF(ISBLANK(Summary!B32),"",IF(LEN(A26)=13,IF(RIGHT(11-MOD(MID(A26,1,1)*13+MID(A26,2,1)*12+MID(A26,3,1)*11+MID(A26,4,1)*10+MID(A26,5,1)*9+MID(A26,6,1)*8+MID(A26,7,1)*7+MID(A26,8,1)*6+MID(A26,9,1)*5+MID(A26,10,1)*4+MID(A26,11,1)*3+MID(A26,12,1)*2,11))=RIGHT(A26),"ถูกต้อง","ผิด "),"ไม่ครบ13หลัก")) | L26: =Summary!N32 -> 0 | N26: =IF(L26="less than 10,000 (น้อยกว่า 10,000)",1,IF(L26="10,001-20,000",2,IF(L26="20,001-30,000",3,IF(L26="30,001-40,000",4,IF(L26="40,001-50,000",5,IF(L26="more than 50,001 (มากกว่า 50,001)",6,7)))))) -> 7
... A101: =IF(ISBLANK(Summary!B107),"",Summary!B107) | B101: =IF(ISBLANK(Summary!B107),"",Summary!C107) | C101: =IF(ISBLANK(Summary!B107),"",Summary!D107) | D101: =IF(ISBLANK(Summary!B107),"",Summary!E107) | E101: =IF(ISBLANK(Summary!B107),"",IF(TRIM(SUBSTITUTE(B101," ",""))="นาย","ชาย",IF(TRIM(SUBSTITUTE(B101," ",""))="นาง","หญิง",IF(TRIM(SUBSTITUTE(B101," ",""))="นางสาว","หญิง",IF(TRIM(SUBSTITUTE(B101," ",""))="น.ส.","หญิง","ระบุคำนำหน้าใม่ถูก"))))) | F101: =IF(ISBLANK(Summary!B107),"",Summary!F107) | G101: =IF(ISBLANK(Summary!B107),"",IF(Summary!Q107="passed","ผ่าน",IF(Summary!Q107="fail","ไม่ผ่าน",""))) | H101: =IF(ISBLANK(Summary!B107),"",CONCATENATE(Summary!G107,Summary!H107,Summary!I107,Summary!J107,Summary!K107,N101)) | I101: =IF(ISBLANK(Summary!B107),"",IF(LEN(A101)=13,IF(RIGHT(11-MOD(MID(A101,1,1)*13+MID(A101,2,1)*12+MID(A101,3,1)*11+MID(A101,4,1)*10+MID(A101,5,1)*9+MID(A101,6,1)*8+MID(A101,7,1)*7+MID(A101,8,1)*6+MID(A101,9,1)*5+MID(A101,10,1)*4+MID(A101,11,1)*3+MID(A101,12,1)*2,11))=RIGHT(A101),"ถูกต้อง","ผิด "),"ไม่ครบ13หลัก")) | L101: =Summary!N107 -> 0 | N101: =IF(L101="less than 10,000 (น้อยกว่า 10,000)",1,IF(L101="10,001-20,000",2,IF(L101="20,001-30,000",3,IF(L101="30,001-40,000",4,IF(L101="40,001-50,000",5,IF(L101="more than 50,001 (มากกว่า 50,001)",6,7)))))) -> 7

Sheet เกณฑ์ผลิตภาพ
A1: หมวดใหญ่ | B1: หมวดย่อย | C1: กลุ่มอุตสหกรรม | D1: กลุ่ม 1 | E1: กลุ่ม 2 | F1: กลุ่ม 3 | G1: กลุ่ม 4 | H1: กลุ่ม 4
A2: A | B2: 1 | C2: A 1 การเพาะปลูกและการเลี้ยงสัตว์ การล่าสัตว์และกิจกรรมบริการที่เกี่ยวข้อง | D2: 0 | E2: 1 | F2: 0 | G2: 1 | H2: 0 | J2: ความรู้
A3: A | B3: 2 | C3: A 2 ป่าไม้และการทำไม้ | D3: 0 | E3: 1 | F3: 0 | G3: 0 | H3: 1 | J3: การปฏิบัติงาน
A4: A | B4: 3 | C4: A 3 การประมงและการเพาะเลี้ยงสัตว์น้ำ | D4: 0 | E4: 1 | F4: 0 | G4: 1 | H4: 1 | J4: ทัศนคติ
A5: B | B5: 5 | C5: B 5 การทำเหมืองถ่านหินและลิกไนต์ | D5: 0 | E5: 1 | F5: 0 | G5: 1 | H5: 0 | J5: การจัดการ
A6: B | B6: 6 | C6: B 6 การผลิตน้ำมันดิบและก๊าซธรรมชาติ | D6: 0 | E6: 1 | F6: 0 | G6: 0 | H6: 1 | J6: ความปลอดภัย
A7: B | B7: 7 | C7: B 7 การทำเหมืองสินแร่โลหะ | D7: 0 | E7: 1 | F7: 1 | G7: 1 | H7: 0
A8: B | B8: 8 | C8: B 8 การทำเหมืองแร่และเหมืองหินอื่น ๆ | D8: 0 | E8: 1 | F8: 0 | G8: 1 | H8: 0
A9: B | B9: 9 | C9: B 9 กิจกรรมบริการที่สนับสนุนการทำเหมืองแร่ และสนับสนุนการผลิตปิโตรเลียม | D9: 0 | E9: 1 | F9: 1 | G9: 1 | H9: 0
A10: C | B10: 10 | C10: C 10 การผลิตผลิตภัณฑ์อาหาร | D10: 0 | E10: 1 | F10: 0 | G10: 1 | H10: 0
A11: C | B11: 11 | C11: C 11 การผลิตเครื่องดื่ม | D11: 0 | E11: 1 | F11: 0 | G11: 1 | H11: 0
A12: C | B12: 12 | C12: C 12 การผลิตสิ่งทอ | D12: 0 | E12: 1 | F12: 0 | G12: 1 | H12: 0
A13: C | B13: 13 | C13: C 13 การผลิตเสื้อผ้าเครื่องแต่งกาย | D13: 0 | E13: 1 | F13: 0 | G13: 1 | H13: 0
